
#######################################################################
# +-----------------------------------------------------------------+ #
# |                            BO3 object                           | #
# +-----------------------------------------------------------------+ #
#######################################################################

Author: Unknown

Description: No description given

Version: 3

SettingsMode: WriteWithoutComments


#######################################################################
# +-----------------------------------------------------------------+ #
# |                          Main settings                          | #
# +-----------------------------------------------------------------+ #
#######################################################################

Tree: true

Frequency: 0

Rarity: 100.0

MaxSpawn: 0

RotateRandomly: false

SpawnHeight: highestBlock

SpawnHeightOffset: 0

SpawnHeightVariance: 0

##############################
# Height Limits for the BO3. #
##############################

MinHeight: 0

MaxHeight: 256

######################
# Extrusion settings #
######################

ExtrudeMode: None

ExtrudeThroughBlocks: minecraft:air

MaxBranchDepth: 10


#######################################################################
# +-----------------------------------------------------------------+ #
# |                      Source block settings                      | #
# +-----------------------------------------------------------------+ #
#######################################################################

SourceBlocks: minecraft:air

MaxPercentageOutsideSourceBlock: 100

OutsideSourceBlock: placeAnyway

DoReplaceBlocks: true

IsOTGPlus: false


#######################################################################
# +-----------------------------------------------------------------+ #
# |                              Blocks                             | #
# +-----------------------------------------------------------------+ #
#######################################################################

B(-8,11,-2,minecraft:oak_leaves[distance=2,persistent=false])
B(-8,11,-1,minecraft:oak_leaves)
B(-8,11,0,minecraft:oak_leaves[distance=2,persistent=false])
B(-8,13,2,minecraft:oak_leaves)
B(-8,14,2,minecraft:oak_leaves[distance=2,persistent=false])
B(-8,12,3,minecraft:oak_leaves)
B(-8,13,3,minecraft:oak_leaves)
B(-8,14,3,minecraft:oak_leaves[distance=2,persistent=false])
B(-8,13,4,minecraft:oak_leaves[distance=2,persistent=false])
B(-7,11,-3,minecraft:oak_leaves[distance=2,persistent=false])
B(-7,11,-2,minecraft:oak_leaves)
B(-7,10,-1,minecraft:oak_leaves)
B(-7,11,-1,minecraft:oak_log)
B(-7,12,-1,minecraft:oak_leaves)
B(-7,11,0,minecraft:oak_leaves)
B(-7,12,0,minecraft:oak_leaves[distance=2,persistent=false])
B(-7,13,1,minecraft:oak_leaves)
B(-7,14,1,minecraft:oak_leaves[distance=2,persistent=false])
B(-7,12,2,minecraft:oak_leaves)
B(-7,13,2,minecraft:oak_log)
B(-7,14,2,minecraft:oak_leaves)
B(-7,12,3,minecraft:oak_log)
B(-7,13,3,minecraft:oak_log)
B(-7,14,3,minecraft:oak_leaves)
B(-7,12,4,minecraft:oak_leaves)
B(-7,13,4,minecraft:oak_leaves)
B(-7,14,4,minecraft:oak_leaves[distance=2,persistent=false])
B(-7,12,5,minecraft:oak_leaves)
B(-7,12,6,minecraft:oak_leaves[distance=2,persistent=false])
B(-6,8,-3,minecraft:oak_leaves[distance=2,persistent=false])
B(-6,8,-2,minecraft:oak_leaves)
B(-6,9,-2,minecraft:oak_leaves[distance=2,persistent=false])
B(-6,8,-1,minecraft:oak_leaves)
B(-6,9,-1,minecraft:oak_leaves[distance=2,persistent=false])
B(-6,10,-1,minecraft:oak_leaves)
B(-6,11,-1,minecraft:oak_leaves)
B(-6,12,-1,minecraft:oak_leaves[distance=2,persistent=false])
B(-6,10,0,minecraft:oak_log)
B(-6,11,0,minecraft:oak_leaves)
B(-6,12,0,minecraft:oak_leaves)
B(-6,13,0,minecraft:oak_leaves[distance=2,persistent=false])
B(-6,12,1,minecraft:oak_leaves[distance=2,persistent=false])
B(-6,13,1,minecraft:oak_leaves[distance=2,persistent=false])
B(-6,14,1,minecraft:oak_leaves[distance=3,persistent=false])
B(-6,12,2,minecraft:oak_leaves)
B(-6,13,2,minecraft:oak_leaves)
B(-6,14,2,minecraft:oak_leaves[distance=2,persistent=false])
B(-6,11,3,minecraft:oak_log)
B(-6,12,3,minecraft:oak_log)
B(-6,13,3,minecraft:oak_leaves)
B(-6,14,3,minecraft:oak_leaves[distance=2,persistent=false])
B(-6,12,4,minecraft:oak_log)
B(-6,13,4,minecraft:oak_leaves)
B(-6,12,5,minecraft:oak_log)
B(-6,13,5,minecraft:oak_leaves)
B(-6,12,6,minecraft:oak_leaves)
B(-5,9,-4,minecraft:oak_leaves[distance=3,persistent=false])
B(-5,8,-3,minecraft:oak_leaves)
B(-5,9,-3,minecraft:oak_leaves[distance=2,persistent=false])
B(-5,8,-2,minecraft:oak_log)
B(-5,9,-2,minecraft:oak_leaves)
B(-5,8,-1,minecraft:oak_log)
B(-5,9,-1,minecraft:oak_leaves)
B(-5,11,-1,minecraft:oak_leaves)
B(-5,12,-1,minecraft:oak_leaves)
B(-5,13,-1,minecraft:oak_leaves[distance=2,persistent=false])
B(-5,11,0,minecraft:oak_log)
B(-5,12,0,minecraft:oak_log)
B(-5,13,0,minecraft:oak_leaves)
B(-5,8,1,minecraft:oak_log)
B(-5,9,1,minecraft:oak_log)
B(-5,12,1,minecraft:oak_leaves)
B(-5,13,1,minecraft:oak_leaves[distance=2,persistent=false])
B(-5,8,2,minecraft:oak_log)
B(-5,9,2,minecraft:oak_log)
B(-5,10,2,minecraft:oak_log)
B(-5,12,2,minecraft:oak_leaves[distance=2,persistent=false])
B(-5,13,2,minecraft:oak_leaves[distance=2,persistent=false])
B(-5,9,3,minecraft:oak_log)
B(-5,10,3,minecraft:oak_log)
B(-5,11,3,minecraft:oak_log)
B(-5,12,3,minecraft:oak_leaves)
B(-5,13,3,minecraft:oak_leaves[distance=2,persistent=false])
B(-5,8,4,minecraft:oak_leaves[distance=2,persistent=false])
B(-5,12,4,minecraft:oak_leaves)
B(-5,13,4,minecraft:oak_leaves[distance=2,persistent=false])
B(-5,8,5,minecraft:oak_leaves[distance=2,persistent=false])
B(-5,12,5,minecraft:oak_leaves)
B(-5,13,5,minecraft:oak_leaves[distance=2,persistent=false])
B(-4,9,-4,minecraft:oak_leaves[distance=2,persistent=false])
B(-4,8,-3,minecraft:oak_leaves)
B(-4,9,-3,minecraft:oak_leaves)
B(-4,8,-2,minecraft:oak_log)
B(-4,9,-2,minecraft:oak_log)
B(-4,10,-2,minecraft:oak_leaves)
B(-4,7,-1,minecraft:oak_log)
B(-4,8,-1,minecraft:oak_log)
B(-4,9,-1,minecraft:oak_log)
B(-4,10,-1,minecraft:oak_leaves)
B(-4,12,-1,minecraft:oak_leaves[distance=2,persistent=false])
B(-4,13,-1,minecraft:oak_leaves[distance=2,persistent=false])
B(-4,7,0,minecraft:oak_log)
B(-4,8,0,minecraft:oak_log)
B(-4,11,0,minecraft:oak_leaves)
B(-4,12,0,minecraft:oak_leaves)
B(-4,13,0,minecraft:oak_leaves)
B(-4,14,0,minecraft:oak_leaves[distance=2,persistent=false])
B(-4,6,1,minecraft:oak_log)
B(-4,7,1,minecraft:oak_log)
B(-4,8,1,minecraft:oak_log)
B(-4,12,1,minecraft:oak_leaves[distance=2,persistent=false])
B(-4,13,1,minecraft:oak_leaves[distance=2,persistent=false])
B(-4,8,2,minecraft:oak_log)
B(-4,9,2,minecraft:oak_log)
B(-4,11,2,minecraft:oak_leaves)
B(-4,12,2,minecraft:oak_leaves)
B(-4,13,2,minecraft:oak_leaves[distance=2,persistent=false])
B(-4,11,3,minecraft:oak_log)
B(-4,12,3,minecraft:oak_log)
B(-4,13,3,minecraft:oak_leaves)
B(-4,8,4,minecraft:oak_leaves)
B(-4,9,4,minecraft:oak_leaves[distance=2,persistent=false])
B(-4,10,4,minecraft:oak_leaves[distance=3,persistent=false])
B(-4,12,4,minecraft:oak_log)
B(-4,13,4,minecraft:oak_leaves)
B(-4,14,4,minecraft:oak_leaves)
B(-4,15,4,minecraft:oak_leaves[distance=2,persistent=false])
B(-4,8,5,minecraft:oak_leaves)
B(-4,9,5,minecraft:oak_leaves[distance=2,persistent=false])
B(-4,12,5,minecraft:oak_leaves)
B(-4,14,5,minecraft:oak_leaves[distance=2,persistent=false])
B(-4,15,5,minecraft:oak_leaves[distance=3,persistent=false])
B(-4,8,6,minecraft:oak_leaves[distance=2,persistent=false])
B(-4,9,6,minecraft:oak_leaves[distance=3,persistent=false])
B(-4,12,6,minecraft:oak_leaves)
B(-3,10,-5,minecraft:oak_leaves)
B(-3,11,-5,minecraft:oak_leaves[distance=2,persistent=false])
B(-3,9,-4,minecraft:oak_leaves[distance=2,persistent=false])
B(-3,10,-4,minecraft:oak_leaves[distance=2,persistent=false])
B(-3,11,-4,minecraft:oak_leaves[distance=3,persistent=false])
B(-3,9,-3,minecraft:oak_leaves)
B(-3,10,-3,minecraft:oak_leaves)
B(-3,11,-3,minecraft:oak_leaves[distance=2,persistent=false])
B(-3,12,-3,minecraft:oak_leaves[distance=2,persistent=false])
B(-3,13,-3,minecraft:oak_leaves[distance=3,persistent=false])
B(-3,9,-2,minecraft:oak_log)
B(-3,10,-2,minecraft:oak_log)
B(-3,11,-2,minecraft:oak_leaves)
B(-3,12,-2,minecraft:oak_leaves)
B(-3,13,-2,minecraft:oak_leaves[distance=2,persistent=false])
B(-3,7,-1,minecraft:oak_log)
B(-3,8,-1,minecraft:oak_log)
B(-3,9,-1,minecraft:oak_log)
B(-3,10,-1,minecraft:oak_leaves)
B(-3,11,-1,minecraft:oak_leaves)
B(-3,12,-1,minecraft:oak_leaves)
B(-3,13,-1,minecraft:oak_leaves)
B(-3,14,-1,minecraft:oak_leaves[distance=2,persistent=false])
B(-3,5,0,minecraft:oak_log)
B(-3,6,0,minecraft:oak_log)
B(-3,7,0,minecraft:oak_log)
B(-3,8,0,minecraft:oak_log)
B(-3,11,0,minecraft:oak_log)
B(-3,12,0,minecraft:oak_log)
B(-3,13,0,minecraft:oak_log)
B(-3,14,0,minecraft:oak_leaves)
B(-3,5,1,minecraft:oak_log)
B(-3,6,1,minecraft:oak_log)
B(-3,7,1,minecraft:oak_log)
B(-3,8,1,minecraft:oak_log)
B(-3,9,1,minecraft:oak_log)
B(-3,10,1,minecraft:oak_log)
B(-3,11,1,minecraft:oak_log)
B(-3,12,1,minecraft:oak_leaves)
B(-3,13,1,minecraft:oak_leaves)
B(-3,14,1,minecraft:oak_leaves[distance=2,persistent=false])
B(-3,9,2,minecraft:oak_log)
B(-3,12,2,minecraft:oak_leaves[distance=2,persistent=false])
B(-3,13,2,minecraft:oak_leaves[distance=2,persistent=false])
B(-3,8,3,minecraft:oak_leaves)
B(-3,9,3,minecraft:oak_leaves)
B(-3,11,3,minecraft:oak_leaves)
B(-3,12,3,minecraft:oak_leaves)
B(-3,13,3,minecraft:oak_leaves)
B(-3,14,3,minecraft:oak_leaves)
B(-3,15,3,minecraft:oak_leaves[distance=2,persistent=false])
B(-3,8,4,minecraft:oak_log)
B(-3,9,4,minecraft:oak_leaves)
B(-3,12,4,minecraft:oak_log)
B(-3,13,4,minecraft:oak_log)
B(-3,14,4,minecraft:oak_log)
B(-3,15,4,minecraft:oak_leaves)
B(-3,8,5,minecraft:oak_log)
B(-3,9,5,minecraft:oak_leaves)
B(-3,12,5,minecraft:oak_log)
B(-3,13,5,minecraft:oak_leaves)
B(-3,14,5,minecraft:oak_leaves)
B(-3,15,5,minecraft:oak_leaves[distance=2,persistent=false])
B(-3,8,6,minecraft:oak_leaves)
B(-3,9,6,minecraft:oak_leaves[distance=2,persistent=false])
B(-3,12,6,minecraft:oak_log)
B(-3,13,6,minecraft:oak_leaves)
B(-3,12,7,minecraft:oak_leaves)
B(-2,10,-6,minecraft:oak_leaves)
B(-2,11,-6,minecraft:oak_leaves[distance=2,persistent=false])
B(-2,9,-5,minecraft:oak_leaves)
B(-2,10,-5,minecraft:oak_log)
B(-2,11,-5,minecraft:oak_leaves)
B(-2,12,-5,minecraft:oak_leaves[distance=2,persistent=false])
B(-2,9,-4,minecraft:oak_leaves)
B(-2,10,-4,minecraft:oak_leaves)
B(-2,12,-4,minecraft:oak_leaves[distance=2,persistent=false])
B(-2,9,-3,minecraft:oak_leaves)
B(-2,11,-3,minecraft:oak_leaves)
B(-2,12,-3,minecraft:oak_leaves)
B(-2,13,-3,minecraft:oak_leaves[distance=2,persistent=false])
B(-2,11,-2,minecraft:oak_log)
B(-2,12,-2,minecraft:oak_log)
B(-2,13,-2,minecraft:oak_leaves)
B(-2,4,-1,minecraft:oak_log)
B(-2,5,-1,minecraft:oak_log)
B(-2,7,-1,minecraft:oak_log)
B(-2,11,-1,minecraft:oak_leaves)
B(-2,12,-1,minecraft:oak_leaves)
B(-2,13,-1,minecraft:oak_leaves[distance=2,persistent=false])
B(-2,4,0,minecraft:oak_log)
B(-2,5,0,minecraft:oak_log)
B(-2,6,0,minecraft:oak_log)
B(-2,7,0,minecraft:oak_log)
B(-2,12,0,minecraft:oak_leaves)
B(-2,13,0,minecraft:oak_leaves)
B(-2,14,0,minecraft:oak_leaves[distance=2,persistent=false])
B(-2,5,1,minecraft:oak_log)
B(-2,6,1,minecraft:oak_log)
B(-2,12,1,minecraft:oak_leaves)
B(-2,13,1,minecraft:oak_leaves[distance=2,persistent=false])
B(-2,6,2,minecraft:oak_log)
B(-2,9,2,minecraft:oak_log)
B(-2,10,2,minecraft:oak_log)
B(-2,13,2,minecraft:oak_leaves[distance=3,persistent=false])
B(-2,7,3,minecraft:oak_log)
B(-2,8,3,minecraft:oak_leaves)
B(-2,10,3,minecraft:oak_log)
B(-2,12,3,minecraft:oak_leaves)
B(-2,13,3,minecraft:oak_leaves[distance=2,persistent=false])
B(-2,7,4,minecraft:oak_log)
B(-2,8,4,minecraft:oak_log)
B(-2,9,4,minecraft:oak_leaves)
B(-2,12,4,minecraft:oak_log)
B(-2,13,4,minecraft:oak_leaves)
B(-2,14,4,minecraft:oak_leaves)
B(-2,15,4,minecraft:oak_leaves[distance=2,persistent=false])
B(-2,8,5,minecraft:oak_leaves)
B(-2,9,5,minecraft:oak_leaves[distance=2,persistent=false])
B(-2,12,5,minecraft:oak_leaves)
B(-2,13,5,minecraft:oak_leaves)
B(-2,14,5,minecraft:oak_leaves[distance=2,persistent=false])
B(-2,8,6,minecraft:oak_leaves[distance=2,persistent=false])
B(-2,12,6,minecraft:oak_leaves)
B(-2,13,6,minecraft:oak_leaves[distance=2,persistent=false])
B(-1,10,-6,minecraft:oak_leaves[distance=2,persistent=false])
B(-1,9,-5,minecraft:oak_leaves)
B(-1,10,-5,minecraft:oak_leaves)
B(-1,11,-5,minecraft:oak_leaves[distance=2,persistent=false])
B(-1,9,-4,minecraft:oak_log)
B(-1,10,-4,minecraft:oak_leaves)
B(-1,11,-4,minecraft:oak_leaves[distance=2,persistent=false])
B(-1,9,-3,minecraft:oak_log)
B(-1,10,-3,minecraft:oak_leaves)
B(-1,11,-3,minecraft:oak_leaves[distance=2,persistent=false])
B(-1,12,-3,minecraft:oak_leaves[distance=2,persistent=false])
B(-1,8,-2,minecraft:oak_log)
B(-1,11,-2,minecraft:oak_leaves)
B(-1,12,-2,minecraft:oak_leaves)
B(-1,13,-2,minecraft:oak_leaves[distance=2,persistent=false])
B(-1,0,-1,minecraft:oak_log)
B(-1,1,-1,minecraft:oak_log)
B(-1,2,-1,minecraft:oak_log)
B(-1,3,-1,minecraft:oak_log)
B(-1,4,-1,minecraft:oak_log)
B(-1,7,-1,minecraft:oak_log)
B(-1,8,-1,minecraft:oak_log)
B(-1,11,-1,minecraft:oak_leaves[distance=2,persistent=false])
B(-1,12,-1,minecraft:oak_leaves[distance=2,persistent=false])
B(-1,13,-1,minecraft:oak_leaves[distance=3,persistent=false])
B(-1,3,0,minecraft:oak_log)
B(-1,4,0,minecraft:oak_log)
B(-1,5,0,minecraft:oak_log)
B(-1,11,0,minecraft:oak_leaves)
B(-1,12,0,minecraft:oak_leaves)
B(-1,13,0,minecraft:oak_leaves[distance=2,persistent=false])
B(-1,14,0,minecraft:oak_leaves[distance=3,persistent=false])
B(-1,10,1,minecraft:oak_log)
B(-1,11,1,minecraft:oak_log)
B(-1,12,1,minecraft:oak_log)
B(-1,13,1,minecraft:oak_leaves)
B(-1,14,1,minecraft:oak_leaves[distance=2,persistent=false])
B(-1,10,2,minecraft:oak_log)
B(-1,12,2,minecraft:oak_leaves)
B(-1,13,2,minecraft:oak_leaves[distance=2,persistent=false])
B(-1,10,3,minecraft:oak_log)
B(-1,12,3,minecraft:oak_log)
B(-1,13,3,minecraft:oak_leaves)
B(-1,8,4,minecraft:oak_leaves)
B(-1,12,4,minecraft:oak_log)
B(-1,13,4,minecraft:oak_log)
B(-1,14,4,minecraft:oak_leaves)
B(-1,12,5,minecraft:oak_leaves)
B(-1,13,5,minecraft:oak_log)
B(-1,14,5,minecraft:oak_leaves)
B(-1,13,6,minecraft:oak_leaves)
B(0,10,-6,minecraft:oak_leaves[distance=2,persistent=false])
B(0,11,-5,minecraft:oak_leaves[distance=3,persistent=false])
B(0,12,-5,minecraft:oak_leaves[distance=4,persistent=false])
B(0,11,-4,minecraft:oak_leaves[distance=3,persistent=false])
B(0,0,-2,minecraft:oak_log)
B(0,1,-2,minecraft:oak_log)
B(0,11,-2,minecraft:oak_leaves[distance=2,persistent=false])
B(0,12,-2,minecraft:oak_leaves[distance=2,persistent=false])
B(0,0,-1,minecraft:oak_log)
B(0,1,-1,minecraft:oak_log)
B(0,2,-1,minecraft:oak_log)
B(0,3,-1,minecraft:oak_log)
B(0,11,-1,minecraft:oak_leaves)
B(0,12,-1,minecraft:oak_leaves)
B(0,13,-1,minecraft:oak_leaves[distance=2,persistent=false])
B(0,14,-1,minecraft:oak_leaves[distance=3,persistent=false])
B(0,0,0,minecraft:oak_log)
B(0,1,0,minecraft:oak_log)
B(0,2,0,minecraft:oak_log)
B(0,3,0,minecraft:oak_log)
B(0,12,0,minecraft:oak_leaves[distance=2,persistent=false])
B(0,13,0,minecraft:oak_leaves[distance=3,persistent=false])
B(0,11,1,minecraft:oak_leaves)
B(0,12,1,minecraft:oak_leaves)
B(0,13,1,minecraft:oak_leaves[distance=2,persistent=false])
B(0,10,2,minecraft:oak_log)
B(0,12,2,minecraft:oak_leaves[distance=2,persistent=false])
B(0,13,2,minecraft:oak_leaves[distance=2,persistent=false])
B(0,12,3,minecraft:oak_leaves)
B(0,13,3,minecraft:oak_leaves)
B(0,12,4,minecraft:oak_leaves)
B(0,13,4,minecraft:oak_log)
B(0,14,4,minecraft:oak_leaves)
B(0,12,5,minecraft:oak_leaves[distance=2,persistent=false])
B(0,13,5,minecraft:oak_leaves)
B(0,13,6,minecraft:oak_leaves[distance=2,persistent=false])
B(1,10,-6,minecraft:oak_leaves)
B(1,11,-6,minecraft:oak_leaves[distance=2,persistent=false])
B(1,9,-5,minecraft:oak_leaves)
B(1,10,-5,minecraft:oak_leaves)
B(1,11,-5,minecraft:oak_leaves[distance=2,persistent=false])
B(1,12,-5,minecraft:oak_leaves[distance=3,persistent=false])
B(1,9,-4,minecraft:oak_leaves[distance=2,persistent=false])
B(1,10,-4,minecraft:oak_leaves[distance=2,persistent=false])
B(1,11,-4,minecraft:oak_leaves[distance=3,persistent=false])
B(1,12,-4,minecraft:oak_leaves[distance=4,persistent=false])
B(1,10,-3,minecraft:oak_leaves[distance=3,persistent=false])
B(1,11,-3,minecraft:oak_leaves[distance=2,persistent=false])
B(1,2,-2,minecraft:oak_log)
B(1,3,-2,minecraft:oak_log)
B(1,4,-2,minecraft:oak_log)
B(1,11,-2,minecraft:oak_leaves)
B(1,12,-2,minecraft:oak_leaves)
B(1,13,-2,minecraft:oak_leaves[distance=2,persistent=false])
B(1,0,-1,minecraft:oak_log)
B(1,1,-1,minecraft:oak_log)
B(1,2,-1,minecraft:oak_log)
B(1,3,-1,minecraft:oak_log)
B(1,4,-1,minecraft:oak_log)
B(1,10,-1,minecraft:oak_log)
B(1,11,-1,minecraft:oak_log)
B(1,12,-1,minecraft:oak_log)
B(1,13,-1,minecraft:oak_leaves)
B(1,14,-1,minecraft:oak_leaves[distance=2,persistent=false])
B(1,0,0,minecraft:oak_log)
B(1,1,0,minecraft:oak_log)
B(1,11,0,minecraft:oak_leaves)
B(1,12,0,minecraft:oak_leaves)
B(1,13,0,minecraft:oak_leaves[distance=2,persistent=false])
B(1,11,1,minecraft:oak_leaves)
B(1,12,1,minecraft:oak_leaves[distance=2,persistent=false])
B(1,13,1,minecraft:oak_leaves[distance=3,persistent=false])
B(1,11,2,minecraft:oak_log)
B(1,12,2,minecraft:oak_leaves)
B(1,13,2,minecraft:oak_leaves[distance=2,persistent=false])
B(1,11,3,minecraft:oak_leaves)
B(1,12,3,minecraft:oak_leaves[distance=2,persistent=false])
B(1,13,3,minecraft:oak_leaves[distance=2,persistent=false])
B(1,13,4,minecraft:oak_leaves)
B(1,14,4,minecraft:oak_leaves[distance=2,persistent=false])
B(1,13,5,minecraft:oak_leaves[distance=2,persistent=false])
B(2,9,-7,minecraft:oak_leaves[distance=2,persistent=false])
B(2,10,-7,minecraft:oak_leaves)
B(2,11,-7,minecraft:oak_leaves[distance=2,persistent=false])
B(2,9,-6,minecraft:oak_leaves)
B(2,10,-6,minecraft:oak_log)
B(2,11,-6,minecraft:oak_leaves)
B(2,9,-5,minecraft:oak_log)
B(2,10,-5,minecraft:oak_log)
B(2,11,-5,minecraft:oak_leaves)
B(2,8,-4,minecraft:oak_log)
B(2,9,-4,minecraft:oak_leaves)
B(2,10,-4,minecraft:oak_leaves)
B(2,11,-4,minecraft:oak_leaves[distance=2,persistent=false])
B(2,12,-4,minecraft:oak_leaves[distance=3,persistent=false])
B(2,7,-3,minecraft:oak_log)
B(2,8,-3,minecraft:oak_log)
B(2,10,-3,minecraft:oak_leaves[distance=2,persistent=false])
B(2,11,-3,minecraft:oak_leaves[distance=2,persistent=false])
B(2,12,-3,minecraft:oak_leaves[distance=3,persistent=false])
B(2,3,-2,minecraft:oak_log)
B(2,4,-2,minecraft:oak_log)
B(2,5,-2,minecraft:oak_log)
B(2,6,-2,minecraft:oak_log)
B(2,7,-2,minecraft:oak_log)
B(2,11,-2,minecraft:oak_leaves)
B(2,12,-2,minecraft:oak_leaves[distance=2,persistent=false])
B(2,3,-1,minecraft:oak_log)
B(2,4,-1,minecraft:oak_log)
B(2,5,-1,minecraft:oak_log)
B(2,9,-1,minecraft:oak_log)
B(2,10,-1,minecraft:oak_log)
B(2,11,-1,minecraft:oak_leaves)
B(2,12,-1,minecraft:oak_leaves)
B(2,13,-1,minecraft:oak_leaves[distance=2,persistent=false])
B(2,10,0,minecraft:oak_log)
B(2,11,0,minecraft:oak_leaves)
B(2,12,0,minecraft:oak_leaves[distance=2,persistent=false])
B(2,13,0,minecraft:oak_leaves[distance=3,persistent=false])
B(2,11,1,minecraft:oak_leaves[distance=2,persistent=false])
B(2,12,1,minecraft:oak_leaves[distance=3,persistent=false])
B(2,13,1,minecraft:oak_leaves[distance=4,persistent=false])
B(2,11,2,minecraft:oak_leaves)
B(2,12,2,minecraft:oak_leaves[distance=2,persistent=false])
B(2,11,3,minecraft:oak_log)
B(2,12,3,minecraft:oak_leaves)
B(2,11,4,minecraft:oak_leaves)
B(3,10,-6,minecraft:oak_leaves)
B(3,11,-6,minecraft:oak_leaves[distance=2,persistent=false])
B(3,10,-5,minecraft:oak_leaves)
B(3,11,-4,minecraft:oak_leaves[distance=2,persistent=false])
B(3,7,-3,minecraft:oak_log)
B(3,11,-3,minecraft:oak_leaves)
B(3,12,-3,minecraft:oak_leaves[distance=2,persistent=false])
B(3,13,-3,minecraft:oak_leaves[distance=2,persistent=false])
B(3,5,-2,minecraft:oak_log)
B(3,6,-2,minecraft:oak_log)
B(3,7,-2,minecraft:oak_log)
B(3,11,-2,minecraft:oak_log)
B(3,12,-2,minecraft:oak_leaves)
B(3,13,-2,minecraft:oak_leaves)
B(3,7,-1,minecraft:oak_log)
B(3,8,-1,minecraft:oak_log)
B(3,9,-1,minecraft:oak_log)
B(3,10,-1,minecraft:oak_log)
B(3,11,-1,minecraft:oak_log)
B(3,12,-1,minecraft:oak_leaves)
B(3,13,-1,minecraft:oak_leaves[distance=2,persistent=false])
B(3,11,0,minecraft:oak_leaves)
B(3,12,0,minecraft:oak_leaves[distance=2,persistent=false])
B(3,10,1,minecraft:oak_leaves[distance=2,persistent=false])
B(3,11,1,minecraft:oak_leaves[distance=2,persistent=false])
B(3,12,1,minecraft:oak_leaves[distance=3,persistent=false])
B(3,11,2,minecraft:oak_leaves)
B(3,12,2,minecraft:oak_leaves[distance=2,persistent=false])
B(3,11,3,minecraft:oak_leaves)
B(3,12,3,minecraft:oak_leaves)
B(3,11,4,minecraft:oak_leaves[distance=2,persistent=false])
B(3,12,4,minecraft:oak_leaves)
B(4,11,-7,minecraft:oak_leaves[distance=4,persistent=false])
B(4,11,-6,minecraft:oak_leaves[distance=3,persistent=false])
B(4,12,-6,minecraft:oak_leaves[distance=4,persistent=false])
B(4,10,-5,minecraft:oak_leaves)
B(4,11,-5,minecraft:oak_leaves[distance=2,persistent=false])
B(4,12,-5,minecraft:oak_leaves[distance=3,persistent=false])
B(4,9,-4,minecraft:oak_leaves)
B(4,10,-4,minecraft:oak_leaves)
B(4,11,-4,minecraft:oak_leaves[distance=2,persistent=false])
B(4,7,-3,minecraft:oak_log)
B(4,8,-3,minecraft:oak_log)
B(4,9,-3,minecraft:oak_leaves)
B(4,10,-3,minecraft:oak_leaves[distance=2,persistent=false])
B(4,12,-3,minecraft:oak_leaves)
B(4,13,-3,minecraft:oak_leaves)
B(4,14,-3,minecraft:oak_leaves[distance=2,persistent=false])
B(4,7,-2,minecraft:oak_log)
B(4,8,-2,minecraft:oak_log)
B(4,12,-2,minecraft:oak_log)
B(4,13,-2,minecraft:oak_log)
B(4,14,-2,minecraft:oak_leaves)
B(4,7,-1,minecraft:oak_log)
B(4,8,-1,minecraft:oak_log)
B(4,9,-1,minecraft:oak_log)
B(4,12,-1,minecraft:oak_leaves)
B(4,13,-1,minecraft:oak_leaves)
B(4,8,0,minecraft:oak_log)
B(4,9,0,minecraft:oak_log)
B(4,11,0,minecraft:oak_leaves)
B(4,12,0,minecraft:oak_leaves[distance=2,persistent=false])
B(4,8,1,minecraft:oak_log)
B(4,9,1,minecraft:oak_log)
B(4,10,1,minecraft:oak_leaves)
B(4,11,1,minecraft:oak_leaves)
B(4,12,1,minecraft:oak_leaves[distance=2,persistent=false])
B(4,11,2,minecraft:oak_log)
B(4,12,2,minecraft:oak_leaves)
B(4,11,3,minecraft:oak_leaves)
B(4,12,3,minecraft:oak_log)
B(4,13,3,minecraft:oak_leaves)
B(4,11,4,minecraft:oak_leaves)
B(4,12,4,minecraft:oak_log)
B(4,13,4,minecraft:oak_leaves)
B(4,12,5,minecraft:oak_leaves)
B(5,11,-7,minecraft:oak_leaves[distance=3,persistent=false])
B(5,9,-6,minecraft:oak_leaves[distance=2,persistent=false])
B(5,10,-6,minecraft:oak_leaves)
B(5,11,-6,minecraft:oak_leaves[distance=2,persistent=false])
B(5,12,-6,minecraft:oak_leaves[distance=3,persistent=false])
B(5,13,-6,minecraft:oak_leaves[distance=4,persistent=false])
B(5,9,-5,minecraft:oak_leaves)
B(5,10,-5,minecraft:oak_log)
B(5,11,-5,minecraft:oak_leaves)
B(5,12,-5,minecraft:oak_leaves[distance=2,persistent=false])
B(5,13,-5,minecraft:oak_leaves[distance=3,persistent=false])
B(5,9,-4,minecraft:oak_log)
B(5,10,-4,minecraft:oak_log)
B(5,11,-4,minecraft:oak_leaves)
B(5,12,-4,minecraft:oak_leaves[distance=2,persistent=false])
B(5,8,-3,minecraft:oak_log)
B(5,9,-3,minecraft:oak_log)
B(5,10,-3,minecraft:oak_leaves)
B(5,11,-3,minecraft:oak_leaves[distance=2,persistent=false])
B(5,13,-3,minecraft:oak_leaves[distance=2,persistent=false])
B(5,12,-2,minecraft:oak_leaves)
B(5,13,-2,minecraft:oak_leaves)
B(5,13,-1,minecraft:oak_leaves[distance=2,persistent=false])
B(5,9,0,minecraft:oak_log)
B(5,11,0,minecraft:oak_log)
B(5,12,0,minecraft:oak_leaves)
B(5,9,1,minecraft:oak_log)
B(5,10,1,minecraft:oak_log)
B(5,11,1,minecraft:oak_log)
B(5,12,1,minecraft:oak_leaves)
B(5,11,2,minecraft:oak_leaves)
B(5,12,2,minecraft:oak_leaves[distance=2,persistent=false])
B(5,11,3,minecraft:oak_leaves)
B(5,12,3,minecraft:oak_leaves)
B(5,13,3,minecraft:oak_leaves[distance=2,persistent=false])
B(5,14,3,minecraft:oak_leaves[distance=3,persistent=false])
B(5,11,4,minecraft:oak_leaves[distance=2,persistent=false])
B(5,12,4,minecraft:oak_leaves)
B(5,13,4,minecraft:oak_leaves[distance=2,persistent=false])
B(5,14,4,minecraft:oak_leaves[distance=3,persistent=false])
B(5,12,5,minecraft:oak_leaves[distance=2,persistent=false])
B(5,13,5,minecraft:oak_leaves[distance=3,persistent=false])
B(6,11,-7,minecraft:oak_leaves[distance=2,persistent=false])
B(6,9,-6,minecraft:oak_leaves[distance=2,persistent=false])
B(6,10,-6,minecraft:oak_leaves)
B(6,11,-6,minecraft:oak_leaves)
B(6,12,-6,minecraft:oak_leaves[distance=2,persistent=false])
B(6,9,-5,minecraft:oak_leaves)
B(6,10,-5,minecraft:oak_log)
B(6,11,-5,minecraft:oak_log)
B(6,12,-5,minecraft:oak_leaves)
B(6,13,-5,minecraft:oak_leaves[distance=2,persistent=false])
B(6,10,-4,minecraft:oak_log)
B(6,11,-4,minecraft:oak_leaves)
B(6,12,-4,minecraft:oak_leaves[distance=2,persistent=false])
B(6,13,-4,minecraft:oak_leaves[distance=3,persistent=false])
B(6,10,-3,minecraft:oak_leaves)
B(6,11,-3,minecraft:oak_leaves[distance=2,persistent=false])
B(6,12,-2,minecraft:oak_leaves)
B(6,13,-2,minecraft:oak_leaves[distance=2,persistent=false])
B(6,12,-1,minecraft:oak_log)
B(6,13,-1,minecraft:oak_leaves)
B(6,12,0,minecraft:oak_leaves)
B(6,13,0,minecraft:oak_leaves[distance=2,persistent=false])
B(6,11,1,minecraft:oak_log)
B(6,12,1,minecraft:oak_leaves)
B(6,11,2,minecraft:oak_log)
B(6,12,2,minecraft:oak_leaves)
B(6,11,3,minecraft:oak_log)
B(6,12,3,minecraft:oak_leaves)
B(6,13,3,minecraft:oak_leaves[distance=2,persistent=false])
B(6,11,4,minecraft:oak_leaves)
B(6,12,4,minecraft:oak_log)
B(6,13,4,minecraft:oak_leaves)
B(6,12,5,minecraft:oak_leaves)
B(7,11,-6,minecraft:oak_leaves[distance=2,persistent=false])
B(7,12,-6,minecraft:oak_leaves)
B(7,10,-5,minecraft:oak_leaves)
B(7,11,-5,minecraft:oak_leaves)
B(7,12,-5,minecraft:oak_log)
B(7,13,-5,minecraft:oak_leaves)
B(7,11,-4,minecraft:oak_leaves[distance=2,persistent=false])
B(7,12,-4,minecraft:oak_leaves)
B(7,13,-4,minecraft:oak_leaves[distance=2,persistent=false])
B(7,12,-2,minecraft:oak_leaves)
B(7,13,-2,minecraft:oak_leaves[distance=2,persistent=false])
B(7,12,-1,minecraft:oak_log)
B(7,13,-1,minecraft:oak_leaves)
B(7,12,0,minecraft:oak_leaves)
B(7,13,0,minecraft:oak_leaves[distance=2,persistent=false])
B(7,11,1,minecraft:oak_log)
B(7,12,1,minecraft:oak_leaves)
B(7,11,2,minecraft:oak_leaves)
B(7,12,2,minecraft:oak_leaves[distance=2,persistent=false])
B(7,12,3,minecraft:oak_leaves[distance=2,persistent=false])
B(7,13,3,minecraft:oak_leaves[distance=3,persistent=false])
B(7,12,4,minecraft:oak_leaves)
B(8,12,-5,minecraft:oak_leaves)
B(8,12,-4,minecraft:oak_leaves[distance=2,persistent=false])
B(8,12,-2,minecraft:oak_leaves[distance=2,persistent=false])
B(8,12,-1,minecraft:oak_leaves)
B(8,13,-1,minecraft:oak_leaves[distance=2,persistent=false])
B(8,11,0,minecraft:oak_leaves[distance=2,persistent=false])
B(8,12,0,minecraft:oak_leaves)
B(8,13,0,minecraft:oak_leaves[distance=2,persistent=false])
B(8,11,1,minecraft:oak_leaves)
B(8,12,1,minecraft:oak_log)
B(8,13,1,minecraft:oak_leaves)
B(8,12,2,minecraft:oak_leaves)
B(8,13,2,minecraft:oak_leaves[distance=2,persistent=false])
B(8,12,3,minecraft:oak_leaves[distance=2,persistent=false])
B(9,12,0,minecraft:oak_leaves[distance=2,persistent=false])
B(9,12,1,minecraft:oak_leaves)

#######################################################################
# +-----------------------------------------------------------------+ #
# |                            BO3 checks                           | #
# +-----------------------------------------------------------------+ #
#######################################################################


#######################################################################
# +-----------------------------------------------------------------+ #
# |                             Branches                            | #
# +-----------------------------------------------------------------+ #
#######################################################################


#######################################################################
# +-----------------------------------------------------------------+ #
# |                             Entities                            | #
# +-----------------------------------------------------------------+ #
#######################################################################

