
#######################################################################
# +-----------------------------------------------------------------+ #
# |                            BO3 object                           | #
# +-----------------------------------------------------------------+ #
#######################################################################

Author: Unknown

Description: No description given

Version: 3

SettingsMode: WriteWithoutComments


#######################################################################
# +-----------------------------------------------------------------+ #
# |                          Main settings                          | #
# +-----------------------------------------------------------------+ #
#######################################################################

Tree: true

Frequency: 0

Rarity: 100.0

MaxSpawn: 0

RotateRandomly: false

SpawnHeight: highestBlock

SpawnHeightOffset: 0

SpawnHeightVariance: 0

##############################
# Height Limits for the BO3. #
##############################

MinHeight: 0

MaxHeight: 256

######################
# Extrusion settings #
######################

ExtrudeMode: None

ExtrudeThroughBlocks: minecraft:air

MaxBranchDepth: 10


#######################################################################
# +-----------------------------------------------------------------+ #
# |                      Source block settings                      | #
# +-----------------------------------------------------------------+ #
#######################################################################

SourceBlocks: minecraft:air

MaxPercentageOutsideSourceBlock: 100

OutsideSourceBlock: placeAnyway

DoReplaceBlocks: true

IsOTGPlus: false


#######################################################################
# +-----------------------------------------------------------------+ #
# |                              Blocks                             | #
# +-----------------------------------------------------------------+ #
#######################################################################

B(-6,17,-1,minecraft:oak_leaves[distance=7,persistent=true])
B(-6,14,1,minecraft:oak_leaves[distance=4,persistent=false])
B(-6,15,3,minecraft:oak_leaves[distance=6,persistent=false])
B(-5,15,-2,minecraft:oak_leaves[distance=5,persistent=false])
B(-5,13,-1,minecraft:oak_leaves[distance=4,persistent=false])
B(-5,14,-1,minecraft:oak_leaves[distance=3,persistent=false])
B(-5,16,-1,minecraft:oak_leaves[distance=7,persistent=true])
B(-5,17,-1,minecraft:oak_leaves[distance=7,persistent=true])
B(-5,13,0,minecraft:oak_leaves[distance=5,persistent=false])
B(-5,14,0,minecraft:oak_leaves[distance=4,persistent=false])
B(-5,16,0,minecraft:oak_leaves[distance=7,persistent=true])
B(-5,12,1,minecraft:oak_leaves[distance=5,persistent=false])
B(-5,13,1,minecraft:oak_leaves[distance=4,persistent=false])
B(-5,14,1,minecraft:oak_leaves[distance=3,persistent=false])
B(-5,15,1,minecraft:oak_leaves[distance=4,persistent=false])
B(-5,11,2,minecraft:oak_leaves[distance=6,persistent=false])
B(-5,13,2,minecraft:oak_leaves[distance=5,persistent=false])
B(-5,14,2,minecraft:oak_leaves[distance=4,persistent=false])
B(-5,16,2,minecraft:oak_leaves[distance=3,persistent=false])
B(-5,12,3,minecraft:oak_leaves[distance=7,persistent=true])
B(-5,15,3,minecraft:oak_leaves[distance=5,persistent=false])
B(-4,16,-3,minecraft:oak_leaves[distance=4,persistent=false])
B(-4,10,-2,minecraft:oak_leaves[distance=4,persistent=false])
B(-4,11,-2,minecraft:oak_leaves[distance=3,persistent=false])
B(-4,13,-2,minecraft:oak_leaves[distance=4,persistent=false])
B(-4,14,-2,minecraft:oak_leaves[distance=3,persistent=false])
B(-4,15,-2,minecraft:oak_leaves[distance=4,persistent=false])
B(-4,17,-2,minecraft:oak_leaves[distance=2,persistent=false])
B(-4,18,-2,minecraft:oak_leaves[distance=3,persistent=false])
B(-4,10,-1,minecraft:oak_leaves[distance=3,persistent=false])
B(-4,11,-1,minecraft:oak_leaves[distance=2,persistent=false])
B(-4,12,-1,minecraft:oak_leaves[distance=3,persistent=false])
B(-4,14,-1,minecraft:oak_leaves[distance=2,persistent=false])
B(-4,15,-1,minecraft:oak_leaves[distance=3,persistent=false])
B(-4,18,-1,minecraft:oak_leaves[distance=4,persistent=false])
B(-4,10,0,minecraft:oak_leaves[distance=4,persistent=false])
B(-4,11,0,minecraft:oak_leaves[distance=3,persistent=false])
B(-4,12,0,minecraft:oak_leaves[distance=4,persistent=false])
B(-4,14,0,minecraft:oak_leaves[distance=3,persistent=false])
B(-4,18,0,minecraft:oak_leaves[distance=3,persistent=false])
B(-4,9,1,minecraft:oak_leaves[distance=6,persistent=false])
B(-4,10,1,minecraft:oak_leaves[distance=5,persistent=false])
B(-4,11,1,minecraft:oak_leaves[distance=4,persistent=false])
B(-4,13,1,minecraft:oak_leaves[distance=3,persistent=false])
B(-4,14,1,minecraft:oak_leaves[distance=2,persistent=false])
B(-4,18,1,minecraft:oak_leaves[distance=3,persistent=false])
B(-4,11,2,minecraft:oak_leaves[distance=5,persistent=false])
B(-4,12,2,minecraft:oak_leaves[distance=5,persistent=false])
B(-4,14,2,minecraft:oak_leaves[distance=3,persistent=false])
B(-4,15,2,minecraft:oak_leaves[distance=3,persistent=false])
B(-4,16,2,minecraft:oak_leaves[distance=2,persistent=false])
B(-4,17,2,minecraft:oak_leaves)
B(-4,10,3,minecraft:oak_leaves[distance=7,persistent=true])
B(-4,11,3,minecraft:oak_leaves[distance=6,persistent=false])
B(-4,12,3,minecraft:oak_leaves[distance=6,persistent=false])
B(-4,13,3,minecraft:oak_leaves[distance=5,persistent=false])
B(-4,14,3,minecraft:oak_leaves[distance=4,persistent=false])
B(-4,15,3,minecraft:oak_leaves[distance=4,persistent=false])
B(-4,16,3,minecraft:oak_leaves[distance=3,persistent=false])
B(-4,12,4,minecraft:oak_leaves[distance=6,persistent=false])
B(-4,14,4,minecraft:oak_leaves[distance=4,persistent=false])
B(-3,12,-5,minecraft:oak_leaves[distance=7,persistent=true])
B(-3,12,-4,minecraft:oak_leaves[distance=7,persistent=true])
B(-3,9,-3,minecraft:oak_leaves[distance=7,persistent=true])
B(-3,10,-3,minecraft:oak_leaves[distance=7,persistent=true])
B(-3,13,-3,minecraft:oak_leaves[distance=4,persistent=false])
B(-3,14,-3,minecraft:oak_leaves[distance=3,persistent=false])
B(-3,16,-3,minecraft:oak_leaves[distance=3,persistent=false])
B(-3,17,-3,minecraft:oak_leaves[distance=2,persistent=false])
B(-3,9,-2,minecraft:oak_leaves[distance=7,persistent=true])
B(-3,11,-2,minecraft:oak_leaves[distance=2,persistent=false])
B(-3,12,-2,minecraft:oak_leaves[distance=3,persistent=false])
B(-3,13,-2,minecraft:oak_leaves[distance=3,persistent=false])
B(-3,14,-2,minecraft:oak_leaves[distance=2,persistent=false])
B(-3,17,-2,minecraft:oak_leaves)
B(-3,18,-2,minecraft:oak_leaves[distance=2,persistent=false])
B(-3,11,-1,minecraft:oak_leaves)
B(-3,13,-1,minecraft:oak_leaves[distance=2,persistent=false])
B(-3,14,-1,minecraft:oak_leaves)
B(-3,15,-1,minecraft:oak_leaves[distance=2,persistent=false])
B(-3,16,-1,minecraft:oak_leaves)
B(-3,17,-1,minecraft:oak_log)
B(-3,19,-1,minecraft:oak_leaves[distance=3,persistent=false])
B(-3,12,0,minecraft:oak_leaves[distance=4,persistent=false])
B(-3,13,0,minecraft:oak_leaves[distance=3,persistent=false])
B(-3,14,0,minecraft:oak_leaves[distance=2,persistent=false])
B(-3,17,0,minecraft:oak_leaves)
B(-3,18,0,minecraft:oak_leaves[distance=2,persistent=false])
B(-3,19,0,minecraft:oak_leaves[distance=3,persistent=false])
B(-3,10,1,minecraft:oak_leaves[distance=6,persistent=false])
B(-3,12,1,minecraft:oak_leaves[distance=3,persistent=false])
B(-3,13,1,minecraft:oak_leaves[distance=2,persistent=false])
B(-3,14,1,minecraft:oak_leaves)
B(-3,15,1,minecraft:oak_leaves[distance=2,persistent=false])
B(-3,17,1,minecraft:oak_leaves)
B(-3,18,1,minecraft:oak_leaves[distance=2,persistent=false])
B(-3,12,2,minecraft:oak_leaves[distance=4,persistent=false])
B(-3,13,2,minecraft:oak_leaves[distance=3,persistent=false])
B(-3,14,2,minecraft:oak_leaves[distance=2,persistent=false])
B(-3,15,2,minecraft:oak_leaves[distance=2,persistent=false])
B(-3,16,2,minecraft:oak_leaves)
B(-3,17,2,minecraft:oak_log)
B(-3,18,2,minecraft:oak_leaves)
B(-3,10,3,minecraft:oak_leaves[distance=7,persistent=true])
B(-3,12,3,minecraft:oak_leaves[distance=5,persistent=false])
B(-3,13,3,minecraft:oak_leaves[distance=4,persistent=false])
B(-3,14,3,minecraft:oak_leaves[distance=3,persistent=false])
B(-3,15,3,minecraft:oak_leaves[distance=3,persistent=false])
B(-3,16,3,minecraft:oak_leaves[distance=2,persistent=false])
B(-3,17,3,minecraft:oak_leaves)
B(-3,11,4,minecraft:oak_leaves[distance=6,persistent=false])
B(-3,12,4,minecraft:oak_leaves[distance=5,persistent=false])
B(-3,14,4,minecraft:oak_leaves[distance=3,persistent=false])
B(-3,15,4,minecraft:oak_leaves[distance=2,persistent=false])
B(-3,10,5,minecraft:oak_leaves[distance=7,persistent=true])
B(-3,14,5,minecraft:oak_leaves[distance=4,persistent=false])
B(-3,15,5,minecraft:oak_leaves[distance=3,persistent=false])
B(-3,16,5,minecraft:oak_leaves[distance=4,persistent=false])
B(-2,11,-5,minecraft:oak_leaves[distance=3,persistent=false])
B(-2,15,-5,minecraft:oak_leaves[distance=4,persistent=false])
B(-2,12,-4,minecraft:oak_leaves[distance=7,persistent=true])
B(-2,15,-4,minecraft:oak_leaves[distance=3,persistent=false])
B(-2,13,-3,minecraft:oak_leaves[distance=3,persistent=false])
B(-2,14,-3,minecraft:oak_leaves[distance=2,persistent=false])
B(-2,15,-3,minecraft:oak_leaves[distance=2,persistent=false])
B(-2,16,-3,minecraft:oak_leaves[distance=2,persistent=false])
B(-2,17,-3,minecraft:oak_leaves[distance=2,persistent=false])
B(-2,11,-2,minecraft:oak_leaves)
B(-2,13,-2,minecraft:oak_leaves[distance=2,persistent=false])
B(-2,14,-2,minecraft:oak_leaves)
B(-2,15,-2,minecraft:oak_leaves)
B(-2,16,-2,minecraft:oak_leaves)
B(-2,17,-2,minecraft:oak_leaves[distance=2,persistent=false])
B(-2,18,-2,minecraft:oak_leaves[distance=2,persistent=false])
B(-2,0,-1,minecraft:oak_log)
B(-2,11,-1,minecraft:oak_log)
B(-2,12,-1,minecraft:oak_leaves)
B(-2,14,-1,minecraft:oak_log)
B(-2,15,-1,minecraft:oak_leaves)
B(-2,16,-1,minecraft:oak_log)
B(-2,17,-1,minecraft:oak_leaves)
B(-2,18,-1,minecraft:oak_leaves)
B(-2,19,-1,minecraft:oak_leaves[distance=2,persistent=false])
B(-2,13,0,minecraft:oak_leaves[distance=2,persistent=false])
B(-2,14,0,minecraft:oak_leaves)
B(-2,18,0,minecraft:oak_leaves[distance=2,persistent=false])
B(-2,19,0,minecraft:oak_leaves[distance=3,persistent=false])
B(-2,13,1,minecraft:oak_leaves)
B(-2,14,1,minecraft:oak_log)
B(-2,16,1,minecraft:oak_leaves)
B(-2,17,1,minecraft:oak_log)
B(-2,18,1,minecraft:oak_leaves)
B(-2,19,1,minecraft:oak_leaves[distance=2,persistent=false])
B(-2,0,2,minecraft:oak_log)
B(-2,11,2,minecraft:oak_log)
B(-2,13,2,minecraft:oak_leaves[distance=2,persistent=false])
B(-2,17,2,minecraft:oak_leaves)
B(-2,12,3,minecraft:oak_leaves[distance=4,persistent=false])
B(-2,13,3,minecraft:oak_leaves[distance=3,persistent=false])
B(-2,14,3,minecraft:oak_leaves[distance=3,persistent=false])
B(-2,15,3,minecraft:oak_leaves[distance=2,persistent=false])
B(-2,16,3,minecraft:oak_leaves[distance=2,persistent=false])
B(-2,18,3,minecraft:oak_leaves[distance=4,persistent=false])
B(-2,11,4,minecraft:oak_leaves[distance=5,persistent=false])
B(-2,12,4,minecraft:oak_leaves[distance=4,persistent=false])
B(-2,13,4,minecraft:oak_leaves[distance=3,persistent=false])
B(-2,14,4,minecraft:oak_leaves[distance=2,persistent=false])
B(-2,15,4,minecraft:oak_leaves)
B(-2,17,4,minecraft:oak_leaves[distance=3,persistent=false])
B(-2,11,5,minecraft:oak_leaves[distance=6,persistent=false])
B(-2,12,5,minecraft:oak_leaves[distance=5,persistent=false])
B(-2,13,5,minecraft:oak_leaves[distance=4,persistent=false])
B(-2,14,5,minecraft:oak_leaves[distance=3,persistent=false])
B(-2,15,5,minecraft:oak_leaves[distance=2,persistent=false])
B(-2,16,5,minecraft:oak_leaves[distance=3,persistent=false])
B(-2,17,5,minecraft:oak_leaves[distance=4,persistent=false])
B(-2,13,6,minecraft:oak_leaves[distance=5,persistent=false])
B(-2,15,6,minecraft:oak_leaves[distance=3,persistent=false])
B(-1,10,-5,minecraft:oak_leaves[distance=3,persistent=false])
B(-1,11,-5,minecraft:oak_leaves[distance=2,persistent=false])
B(-1,12,-5,minecraft:oak_leaves[distance=3,persistent=false])
B(-1,14,-5,minecraft:oak_leaves[distance=4,persistent=false])
B(-1,11,-4,minecraft:oak_leaves)
B(-1,15,-4,minecraft:oak_leaves[distance=2,persistent=false])
B(-1,16,-4,minecraft:oak_leaves[distance=2,persistent=false])
B(-1,17,-4,minecraft:oak_leaves[distance=2,persistent=false])
B(-1,18,-4,minecraft:oak_leaves[distance=3,persistent=false])
B(-1,10,-3,minecraft:oak_leaves[distance=4,persistent=false])
B(-1,12,-3,minecraft:oak_leaves)
B(-1,13,-3,minecraft:oak_leaves[distance=2,persistent=false])
B(-1,14,-3,minecraft:oak_leaves[distance=2,persistent=false])
B(-1,15,-3,minecraft:oak_leaves)
B(-1,16,-3,minecraft:oak_leaves)
B(-1,17,-3,minecraft:oak_leaves)
B(-1,18,-3,minecraft:oak_leaves[distance=2,persistent=false])
B(-1,19,-3,minecraft:oak_leaves[distance=3,persistent=false])
B(-1,10,-2,minecraft:oak_leaves[distance=3,persistent=false])
B(-1,11,-2,minecraft:oak_leaves[distance=2,persistent=false])
B(-1,12,-2,minecraft:oak_leaves)
B(-1,13,-2,minecraft:oak_leaves)
B(-1,14,-2,minecraft:oak_leaves)
B(-1,15,-2,minecraft:oak_log)
B(-1,17,-2,minecraft:oak_leaves)
B(-1,18,-2,minecraft:oak_leaves)
B(-1,19,-2,minecraft:oak_leaves[distance=2,persistent=false])
B(-1,12,-1,minecraft:oak_log)
B(-1,16,-1,minecraft:oak_leaves)
B(-1,17,-1,minecraft:oak_log)
B(-1,18,-1,minecraft:oak_log)
B(-1,19,-1,minecraft:oak_leaves)
B(-1,0,0,minecraft:oak_log)
B(-1,1,0,minecraft:oak_log)
B(-1,2,0,minecraft:oak_log)
B(-1,3,0,minecraft:oak_log)
B(-1,4,0,minecraft:oak_log)
B(-1,5,0,minecraft:oak_log)
B(-1,13,0,minecraft:oak_leaves[distance=3,persistent=false])
B(-1,16,0,minecraft:oak_leaves)
B(-1,17,0,minecraft:oak_leaves)
B(-1,19,0,minecraft:oak_leaves[distance=2,persistent=false])
B(-1,0,1,minecraft:oak_log)
B(-1,1,1,minecraft:oak_log)
B(-1,2,1,minecraft:oak_log)
B(-1,10,1,minecraft:oak_log)
B(-1,14,1,minecraft:oak_log)
B(-1,15,1,minecraft:oak_log)
B(-1,16,1,minecraft:oak_log)
B(-1,17,1,minecraft:oak_leaves)
B(-1,19,1,minecraft:oak_leaves[distance=3,persistent=false])
B(-1,11,2,minecraft:oak_leaves)
B(-1,14,2,minecraft:oak_leaves)
B(-1,16,2,minecraft:oak_log)
B(-1,17,2,minecraft:oak_leaves)
B(-1,18,2,minecraft:oak_leaves[distance=2,persistent=false])
B(-1,19,2,minecraft:oak_leaves[distance=3,persistent=false])
B(-1,12,3,minecraft:oak_leaves[distance=3,persistent=false])
B(-1,14,3,minecraft:oak_leaves[distance=2,persistent=false])
B(-1,15,3,minecraft:oak_leaves)
B(-1,16,3,minecraft:oak_leaves)
B(-1,17,3,minecraft:oak_leaves[distance=2,persistent=false])
B(-1,18,3,minecraft:oak_leaves[distance=3,persistent=false])
B(-1,11,4,minecraft:oak_leaves[distance=6,persistent=false])
B(-1,13,4,minecraft:oak_leaves[distance=2,persistent=false])
B(-1,14,4,minecraft:oak_leaves)
B(-1,15,4,minecraft:oak_log)
B(-1,16,4,minecraft:oak_leaves)
B(-1,17,4,minecraft:oak_leaves[distance=2,persistent=false])
B(-1,18,4,minecraft:oak_leaves[distance=3,persistent=false])
B(-1,12,5,minecraft:oak_leaves[distance=4,persistent=false])
B(-1,13,5,minecraft:oak_leaves[distance=3,persistent=false])
B(-1,14,5,minecraft:oak_leaves[distance=2,persistent=false])
B(-1,15,5,minecraft:oak_leaves)
B(-1,16,5,minecraft:oak_leaves[distance=2,persistent=false])
B(-1,17,5,minecraft:oak_leaves[distance=3,persistent=false])
B(-1,13,6,minecraft:oak_leaves[distance=4,persistent=false])
B(-1,14,6,minecraft:oak_leaves[distance=3,persistent=false])
B(-1,15,6,minecraft:oak_leaves[distance=2,persistent=false])
B(-1,16,6,minecraft:oak_leaves[distance=3,persistent=false])
B(0,11,-6,minecraft:oak_leaves[distance=2,persistent=false])
B(0,12,-6,minecraft:oak_leaves[distance=3,persistent=false])
B(0,15,-6,minecraft:oak_leaves[distance=3,persistent=false])
B(0,16,-6,minecraft:oak_leaves[distance=3,persistent=false])
B(0,11,-5,minecraft:oak_leaves)
B(0,14,-5,minecraft:oak_leaves[distance=3,persistent=false])
B(0,15,-5,minecraft:oak_leaves[distance=2,persistent=false])
B(0,16,-5,minecraft:oak_leaves[distance=2,persistent=false])
B(0,17,-5,minecraft:oak_leaves[distance=2,persistent=false])
B(0,18,-5,minecraft:oak_leaves[distance=3,persistent=false])
B(0,11,-4,minecraft:oak_log)
B(0,12,-4,minecraft:oak_leaves)
B(0,13,-4,minecraft:oak_leaves[distance=2,persistent=false])
B(0,14,-4,minecraft:oak_leaves[distance=3,persistent=false])
B(0,15,-4,minecraft:oak_leaves[distance=2,persistent=false])
B(0,16,-4,minecraft:oak_leaves)
B(0,17,-4,minecraft:oak_leaves)
B(0,19,-4,minecraft:oak_leaves[distance=7,persistent=true])
B(0,12,-3,minecraft:oak_log)
B(0,13,-3,minecraft:oak_leaves)
B(0,14,-3,minecraft:oak_leaves[distance=2,persistent=false])
B(0,15,-3,minecraft:oak_leaves)
B(0,16,-3,minecraft:oak_log)
B(0,17,-3,minecraft:oak_log)
B(0,18,-3,minecraft:oak_leaves)
B(0,12,-2,minecraft:oak_log)
B(0,13,-2,minecraft:oak_log)
B(0,15,-2,minecraft:oak_leaves)
B(0,16,-2,minecraft:oak_leaves)
B(0,17,-2,minecraft:oak_leaves)
B(0,18,-2,minecraft:oak_leaves[distance=2,persistent=false])
B(0,0,-1,minecraft:oak_log)
B(0,10,-1,minecraft:oak_leaves)
B(0,11,-1,minecraft:oak_log)
B(0,15,-1,minecraft:oak_leaves[distance=2,persistent=false])
B(0,16,-1,minecraft:oak_leaves[distance=2,persistent=false])
B(0,17,-1,minecraft:oak_leaves)
B(0,19,-1,minecraft:oak_leaves[distance=2,persistent=false])
B(0,20,-1,minecraft:oak_leaves[distance=3,persistent=false])
B(0,0,0,minecraft:oak_log)
B(0,1,0,minecraft:oak_log)
B(0,2,0,minecraft:oak_log)
B(0,3,0,minecraft:oak_log)
B(0,4,0,minecraft:oak_log)
B(0,5,0,minecraft:oak_log)
B(0,6,0,minecraft:oak_log)
B(0,7,0,minecraft:oak_log)
B(0,8,0,minecraft:oak_log)
B(0,9,0,minecraft:oak_log)
B(0,10,0,minecraft:oak_log)
B(0,16,0,minecraft:oak_leaves[distance=2,persistent=false])
B(0,19,0,minecraft:oak_leaves[distance=3,persistent=false])
B(0,20,0,minecraft:oak_leaves[distance=4,persistent=false])
B(0,0,1,minecraft:oak_log)
B(0,1,1,minecraft:oak_log)
B(0,2,1,minecraft:oak_log)
B(0,3,1,minecraft:oak_log)
B(0,10,1,minecraft:oak_log)
B(0,11,1,minecraft:oak_log)
B(0,12,1,minecraft:oak_log)
B(0,13,1,minecraft:oak_log)
B(0,16,1,minecraft:oak_leaves)
B(0,19,1,minecraft:oak_leaves[distance=4,persistent=false])
B(0,0,2,minecraft:oak_log)
B(0,11,2,minecraft:oak_leaves)
B(0,12,2,minecraft:oak_leaves)
B(0,16,2,minecraft:oak_leaves)
B(0,17,2,minecraft:oak_leaves[distance=2,persistent=false])
B(0,18,2,minecraft:oak_leaves[distance=3,persistent=false])
B(0,19,2,minecraft:oak_leaves[distance=4,persistent=false])
B(0,10,3,minecraft:oak_leaves[distance=3,persistent=false])
B(0,11,3,minecraft:oak_leaves[distance=2,persistent=false])
B(0,12,3,minecraft:oak_leaves[distance=2,persistent=false])
B(0,16,3,minecraft:oak_leaves)
B(0,18,3,minecraft:oak_leaves[distance=3,persistent=false])
B(0,12,4,minecraft:oak_leaves[distance=3,persistent=false])
B(0,13,4,minecraft:oak_leaves[distance=3,persistent=false])
B(0,14,4,minecraft:oak_leaves[distance=2,persistent=false])
B(0,15,4,minecraft:oak_leaves)
B(0,16,4,minecraft:oak_leaves[distance=2,persistent=false])
B(0,18,4,minecraft:oak_leaves[distance=4,persistent=false])
B(0,10,5,minecraft:oak_leaves[distance=7,persistent=true])
B(0,11,5,minecraft:oak_leaves[distance=7,persistent=true])
B(0,13,5,minecraft:oak_leaves[distance=4,persistent=false])
B(0,14,5,minecraft:oak_leaves[distance=3,persistent=false])
B(0,15,5,minecraft:oak_leaves[distance=2,persistent=false])
B(0,16,5,minecraft:oak_leaves[distance=3,persistent=false])
B(0,17,5,minecraft:oak_leaves[distance=4,persistent=false])
B(0,15,6,minecraft:oak_leaves[distance=3,persistent=false])
B(1,14,-6,minecraft:oak_leaves[distance=3,persistent=false])
B(1,15,-6,minecraft:oak_leaves[distance=2,persistent=false])
B(1,16,-6,minecraft:oak_leaves[distance=3,persistent=false])
B(1,10,-5,minecraft:oak_leaves[distance=7,persistent=true])
B(1,13,-5,minecraft:oak_leaves[distance=3,persistent=false])
B(1,15,-5,minecraft:oak_leaves)
B(1,17,-5,minecraft:oak_leaves[distance=2,persistent=false])
B(1,18,-5,minecraft:oak_leaves[distance=3,persistent=false])
B(1,9,-4,minecraft:oak_leaves[distance=7,persistent=true])
B(1,11,-4,minecraft:oak_leaves)
B(1,13,-4,minecraft:oak_leaves[distance=3,persistent=false])
B(1,15,-4,minecraft:oak_leaves)
B(1,16,-4,minecraft:oak_leaves[distance=2,persistent=false])
B(1,18,-4,minecraft:oak_leaves[distance=2,persistent=false])
B(1,9,-3,minecraft:oak_leaves[distance=7,persistent=true])
B(1,14,-3,minecraft:oak_leaves[distance=3,persistent=false])
B(1,16,-3,minecraft:oak_leaves)
B(1,17,-3,minecraft:oak_leaves)
B(1,18,-3,minecraft:oak_leaves[distance=2,persistent=false])
B(1,19,-3,minecraft:oak_leaves[distance=3,persistent=false])
B(1,11,-2,minecraft:oak_leaves[distance=7,persistent=true])
B(1,15,-2,minecraft:oak_leaves)
B(1,16,-2,minecraft:oak_leaves[distance=2,persistent=false])
B(1,19,-2,minecraft:oak_leaves[distance=4,persistent=false])
B(1,20,-2,minecraft:oak_leaves[distance=4,persistent=false])
B(1,9,-1,minecraft:oak_log)
B(1,10,-1,minecraft:oak_log)
B(1,16,-1,minecraft:oak_leaves)
B(1,17,-1,minecraft:oak_leaves[distance=2,persistent=false])
B(1,20,-1,minecraft:oak_leaves[distance=3,persistent=false])
B(1,0,0,minecraft:oak_log)
B(1,1,0,minecraft:oak_log)
B(1,12,0,minecraft:oak_leaves)
B(1,14,0,minecraft:oak_leaves[distance=3,persistent=false])
B(1,16,0,minecraft:oak_leaves[distance=2,persistent=false])
B(1,18,0,minecraft:oak_leaves[distance=2,persistent=false])
B(1,19,0,minecraft:oak_leaves[distance=3,persistent=false])
B(1,20,0,minecraft:oak_leaves[distance=4,persistent=false])
B(1,12,1,minecraft:oak_log)
B(1,13,1,minecraft:oak_leaves)
B(1,14,1,minecraft:oak_leaves[distance=2,persistent=false])
B(1,17,1,minecraft:oak_log)
B(1,18,1,minecraft:oak_leaves)
B(1,20,1,minecraft:oak_leaves[distance=5,persistent=false])
B(1,12,2,minecraft:oak_log)
B(1,13,2,minecraft:oak_leaves)
B(1,17,2,minecraft:oak_leaves)
B(1,18,2,minecraft:oak_leaves[distance=2,persistent=false])
B(1,20,2,minecraft:oak_leaves[distance=6,persistent=false])
B(1,11,3,minecraft:oak_leaves[distance=3,persistent=false])
B(1,13,3,minecraft:oak_log)
B(1,14,3,minecraft:oak_log)
B(1,15,3,minecraft:oak_log)
B(1,16,3,minecraft:oak_log)
B(1,17,3,minecraft:oak_leaves)
B(1,18,3,minecraft:oak_leaves[distance=2,persistent=false])
B(1,19,3,minecraft:oak_leaves[distance=3,persistent=false])
B(1,12,4,minecraft:oak_leaves[distance=3,persistent=false])
B(1,14,4,minecraft:oak_leaves)
B(1,16,4,minecraft:oak_leaves)
B(1,17,4,minecraft:oak_leaves[distance=2,persistent=false])
B(1,18,4,minecraft:oak_leaves[distance=3,persistent=false])
B(1,12,5,minecraft:oak_leaves[distance=4,persistent=false])
B(1,13,5,minecraft:oak_leaves[distance=5,persistent=false])
B(1,15,5,minecraft:oak_leaves[distance=3,persistent=false])
B(2,14,-6,minecraft:oak_leaves[distance=2,persistent=false])
B(2,15,-6,minecraft:oak_leaves)
B(2,16,-6,minecraft:oak_leaves[distance=2,persistent=false])
B(2,11,-5,minecraft:oak_leaves[distance=3,persistent=false])
B(2,12,-5,minecraft:oak_leaves[distance=3,persistent=false])
B(2,13,-5,minecraft:oak_leaves[distance=2,persistent=false])
B(2,14,-5,minecraft:oak_leaves)
B(2,15,-5,minecraft:oak_log)
B(2,16,-5,minecraft:oak_leaves)
B(2,17,-5,minecraft:oak_leaves)
B(2,10,-4,minecraft:oak_leaves[distance=3,persistent=false])
B(2,11,-4,minecraft:oak_leaves[distance=2,persistent=false])
B(2,14,-4,minecraft:oak_leaves)
B(2,15,-4,minecraft:oak_log)
B(2,16,-4,minecraft:oak_leaves)
B(2,17,-4,minecraft:oak_log)
B(2,18,-4,minecraft:oak_leaves)
B(2,10,-3,minecraft:oak_leaves[distance=4,persistent=false])
B(2,11,-3,minecraft:oak_leaves[distance=3,persistent=false])
B(2,13,-3,minecraft:oak_leaves[distance=7,persistent=true])
B(2,15,-3,minecraft:oak_leaves)
B(2,16,-3,minecraft:oak_log)
B(2,19,-3,minecraft:oak_leaves[distance=4,persistent=false])
B(2,20,-3,minecraft:oak_leaves[distance=4,persistent=false])
B(2,15,-2,minecraft:oak_log)
B(2,17,-2,minecraft:oak_leaves[distance=2,persistent=false])
B(2,19,-2,minecraft:oak_leaves[distance=4,persistent=false])
B(2,20,-2,minecraft:oak_leaves[distance=3,persistent=false])
B(2,11,-1,minecraft:oak_log)
B(2,13,-1,minecraft:oak_leaves[distance=7,persistent=true])
B(2,16,-1,minecraft:oak_log)
B(2,17,-1,minecraft:oak_leaves)
B(2,20,-1,minecraft:oak_leaves[distance=2,persistent=false])
B(2,12,0,minecraft:oak_leaves)
B(2,14,0,minecraft:oak_leaves[distance=2,persistent=false])
B(2,15,0,minecraft:oak_leaves[distance=2,persistent=false])
B(2,18,0,minecraft:oak_leaves[distance=3,persistent=false])
B(2,20,0,minecraft:oak_leaves[distance=3,persistent=false])
B(2,12,1,minecraft:oak_log)
B(2,14,1,minecraft:oak_leaves)
B(2,15,1,minecraft:oak_leaves)
B(2,16,1,minecraft:oak_log)
B(2,18,1,minecraft:oak_leaves[distance=2,persistent=false])
B(2,20,1,minecraft:oak_leaves[distance=4,persistent=false])
B(2,13,2,minecraft:oak_leaves[distance=2,persistent=false])
B(2,14,2,minecraft:oak_leaves[distance=2,persistent=false])
B(2,18,2,minecraft:oak_leaves[distance=3,persistent=false])
B(2,19,2,minecraft:oak_leaves[distance=4,persistent=false])
B(2,12,3,minecraft:oak_leaves[distance=3,persistent=false])
B(2,14,3,minecraft:oak_leaves)
B(2,15,3,minecraft:oak_leaves)
B(2,18,3,minecraft:oak_leaves[distance=3,persistent=false])
B(2,11,4,minecraft:oak_leaves[distance=3,persistent=false])
B(2,12,4,minecraft:oak_leaves[distance=2,persistent=false])
B(2,13,4,minecraft:oak_leaves)
B(2,14,4,minecraft:oak_log)
B(2,16,4,minecraft:oak_leaves[distance=2,persistent=false])
B(2,17,4,minecraft:oak_leaves[distance=3,persistent=false])
B(2,12,5,minecraft:oak_leaves[distance=3,persistent=false])
B(2,14,5,minecraft:oak_leaves)
B(2,15,5,minecraft:oak_leaves[distance=2,persistent=false])
B(2,16,5,minecraft:oak_leaves[distance=3,persistent=false])
B(3,15,-6,minecraft:oak_leaves[distance=2,persistent=false])
B(3,12,-5,minecraft:oak_leaves[distance=3,persistent=false])
B(3,14,-5,minecraft:oak_leaves)
B(3,15,-5,minecraft:oak_leaves)
B(3,16,-5,minecraft:oak_leaves[distance=2,persistent=false])
B(3,17,-5,minecraft:oak_leaves[distance=2,persistent=false])
B(3,9,-4,minecraft:oak_leaves[distance=5,persistent=false])
B(3,10,-4,minecraft:oak_leaves[distance=4,persistent=false])
B(3,12,-4,minecraft:oak_leaves[distance=2,persistent=false])
B(3,13,-4,minecraft:oak_leaves)
B(3,14,-4,minecraft:oak_log)
B(3,15,-4,minecraft:oak_leaves)
B(3,16,-4,minecraft:oak_leaves[distance=2,persistent=false])
B(3,17,-4,minecraft:oak_leaves)
B(3,18,-4,minecraft:oak_leaves[distance=2,persistent=false])
B(3,11,-3,minecraft:oak_leaves[distance=3,persistent=false])
B(3,12,-3,minecraft:oak_leaves[distance=3,persistent=false])
B(3,16,-3,minecraft:oak_leaves)
B(3,17,-3,minecraft:oak_leaves[distance=2,persistent=false])
B(3,18,-3,minecraft:oak_leaves[distance=2,persistent=false])
B(3,19,-3,minecraft:oak_leaves[distance=3,persistent=false])
B(3,11,-2,minecraft:oak_leaves[distance=2,persistent=false])
B(3,13,-2,minecraft:oak_log)
B(3,16,-2,minecraft:oak_leaves[distance=2,persistent=false])
B(3,17,-2,minecraft:oak_leaves[distance=2,persistent=false])
B(3,20,-2,minecraft:oak_leaves[distance=2,persistent=false])
B(3,11,-1,minecraft:oak_leaves)
B(3,12,-1,minecraft:oak_log)
B(3,13,-1,minecraft:oak_log)
B(3,14,-1,minecraft:oak_log)
B(3,15,-1,minecraft:oak_log)
B(3,16,-1,minecraft:oak_leaves)
B(3,18,-1,minecraft:oak_leaves)
B(3,19,-1,minecraft:oak_log)
B(3,20,-1,minecraft:oak_leaves)
B(3,11,0,minecraft:oak_leaves)
B(3,12,0,minecraft:oak_leaves)
B(3,13,0,minecraft:oak_leaves)
B(3,14,0,minecraft:oak_leaves)
B(3,20,0,minecraft:oak_leaves[distance=2,persistent=false])
B(3,11,1,minecraft:oak_log)
B(3,13,1,minecraft:oak_log)
B(3,14,1,minecraft:oak_log)
B(3,15,1,minecraft:oak_log)
B(3,16,1,minecraft:oak_log)
B(3,18,1,minecraft:oak_leaves[distance=3,persistent=false])
B(3,20,1,minecraft:oak_leaves[distance=3,persistent=false])
B(3,11,2,minecraft:oak_leaves)
B(3,13,2,minecraft:oak_leaves)
B(3,16,2,minecraft:oak_log)
B(3,18,2,minecraft:oak_leaves[distance=3,persistent=false])
B(3,19,2,minecraft:oak_leaves[distance=4,persistent=false])
B(3,10,3,minecraft:oak_leaves[distance=3,persistent=false])
B(3,11,3,minecraft:oak_leaves[distance=2,persistent=false])
B(3,12,3,minecraft:oak_leaves[distance=3,persistent=false])
B(3,13,3,minecraft:oak_leaves[distance=2,persistent=false])
B(3,15,3,minecraft:oak_leaves[distance=2,persistent=false])
B(3,16,3,minecraft:oak_leaves)
B(3,17,3,minecraft:oak_leaves[distance=2,persistent=false])
B(3,18,3,minecraft:oak_leaves[distance=3,persistent=false])
B(3,11,4,minecraft:oak_leaves[distance=3,persistent=false])
B(3,12,4,minecraft:oak_leaves[distance=3,persistent=false])
B(3,13,4,minecraft:oak_leaves[distance=2,persistent=false])
B(3,14,4,minecraft:oak_leaves)
B(3,15,4,minecraft:oak_leaves[distance=2,persistent=false])
B(3,17,4,minecraft:oak_leaves[distance=3,persistent=false])
B(3,15,5,minecraft:oak_leaves[distance=3,persistent=false])
B(4,13,-5,minecraft:oak_leaves[distance=3,persistent=false])
B(4,14,-5,minecraft:oak_leaves[distance=2,persistent=false])
B(4,12,-4,minecraft:oak_leaves[distance=3,persistent=false])
B(4,14,-4,minecraft:oak_leaves)
B(4,15,-4,minecraft:oak_leaves[distance=2,persistent=false])
B(4,16,-4,minecraft:oak_leaves[distance=3,persistent=false])
B(4,18,-4,minecraft:oak_leaves[distance=2,persistent=false])
B(4,10,-3,minecraft:oak_leaves[distance=4,persistent=false])
B(4,11,-3,minecraft:oak_leaves[distance=3,persistent=false])
B(4,12,-3,minecraft:oak_leaves[distance=4,persistent=false])
B(4,13,-3,minecraft:oak_leaves[distance=3,persistent=false])
B(4,14,-3,minecraft:oak_leaves[distance=2,persistent=false])
B(4,15,-3,minecraft:oak_leaves[distance=2,persistent=false])
B(4,16,-3,minecraft:oak_leaves[distance=2,persistent=false])
B(4,18,-3,minecraft:oak_leaves)
B(4,19,-3,minecraft:oak_leaves[distance=2,persistent=false])
B(4,10,-2,minecraft:oak_leaves[distance=3,persistent=false])
B(4,11,-2,minecraft:oak_leaves[distance=2,persistent=false])
B(4,15,-2,minecraft:oak_leaves)
B(4,16,-2,minecraft:oak_leaves)
B(4,17,-2,minecraft:oak_leaves)
B(4,18,-2,minecraft:oak_log)
B(4,19,-2,minecraft:oak_leaves)
B(4,10,-1,minecraft:oak_leaves[distance=2,persistent=false])
B(4,11,-1,minecraft:oak_leaves)
B(4,12,-1,minecraft:oak_log)
B(4,15,-1,minecraft:oak_log)
B(4,16,-1,minecraft:oak_log)
B(4,17,-1,minecraft:oak_log)
B(4,18,-1,minecraft:oak_log)
B(4,19,-1,minecraft:oak_leaves)
B(4,20,-1,minecraft:oak_leaves[distance=2,persistent=false])
B(4,11,0,minecraft:oak_leaves[distance=2,persistent=false])
B(4,12,0,minecraft:oak_leaves)
B(4,14,0,minecraft:oak_leaves[distance=2,persistent=false])
B(4,16,0,minecraft:oak_leaves)
B(4,17,0,minecraft:oak_leaves)
B(4,19,0,minecraft:oak_leaves[distance=2,persistent=false])
B(4,9,1,minecraft:oak_leaves[distance=3,persistent=false])
B(4,10,1,minecraft:oak_leaves[distance=2,persistent=false])
B(4,11,1,minecraft:oak_leaves)
B(4,12,1,minecraft:oak_leaves[distance=2,persistent=false])
B(4,15,1,minecraft:oak_leaves)
B(4,17,1,minecraft:oak_log)
B(4,19,1,minecraft:oak_leaves[distance=3,persistent=false])
B(4,20,1,minecraft:oak_leaves[distance=4,persistent=false])
B(4,11,2,minecraft:oak_leaves[distance=2,persistent=false])
B(4,13,2,minecraft:oak_leaves)
B(4,14,2,minecraft:oak_log)
B(4,17,2,minecraft:oak_leaves)
B(4,18,2,minecraft:oak_leaves[distance=2,persistent=false])
B(4,19,2,minecraft:oak_leaves[distance=3,persistent=false])
B(4,11,3,minecraft:oak_leaves[distance=3,persistent=false])
B(4,12,3,minecraft:oak_leaves[distance=3,persistent=false])
B(4,13,3,minecraft:oak_leaves[distance=2,persistent=false])
B(4,14,3,minecraft:oak_leaves)
B(4,15,3,minecraft:oak_leaves[distance=2,persistent=false])
B(4,16,3,minecraft:oak_leaves[distance=2,persistent=false])
B(4,17,3,minecraft:oak_leaves[distance=2,persistent=false])
B(4,18,3,minecraft:oak_leaves[distance=3,persistent=false])
B(4,12,4,minecraft:oak_leaves[distance=4,persistent=false])
B(4,13,4,minecraft:oak_leaves[distance=3,persistent=false])
B(4,14,4,minecraft:oak_leaves[distance=2,persistent=false])
B(4,15,4,minecraft:oak_leaves[distance=3,persistent=false])
B(4,13,5,minecraft:oak_leaves[distance=4,persistent=false])
B(4,14,5,minecraft:oak_leaves[distance=3,persistent=false])
B(5,12,-5,minecraft:oak_leaves[distance=5,persistent=false])
B(5,15,-5,minecraft:oak_leaves[distance=4,persistent=false])
B(5,12,-4,minecraft:oak_leaves[distance=4,persistent=false])
B(5,13,-4,minecraft:oak_leaves[distance=5,persistent=false])
B(5,15,-4,minecraft:oak_leaves[distance=3,persistent=false])
B(5,16,-4,minecraft:oak_leaves[distance=4,persistent=false])
B(5,11,-3,minecraft:oak_leaves[distance=4,persistent=false])
B(5,13,-3,minecraft:oak_leaves[distance=4,persistent=false])
B(5,14,-3,minecraft:oak_leaves[distance=3,persistent=false])
B(5,15,-3,minecraft:oak_leaves[distance=3,persistent=false])
B(5,16,-3,minecraft:oak_leaves[distance=3,persistent=false])
B(5,17,-3,minecraft:oak_leaves[distance=3,persistent=false])
B(5,12,-2,minecraft:oak_log)
B(5,14,-2,minecraft:oak_leaves[distance=3,persistent=false])
B(5,15,-2,minecraft:oak_leaves[distance=2,persistent=false])
B(5,17,-2,minecraft:oak_leaves[distance=2,persistent=false])
B(5,18,-2,minecraft:oak_leaves)
B(5,19,-2,minecraft:oak_leaves[distance=2,persistent=false])
B(5,10,-1,minecraft:oak_leaves[distance=3,persistent=false])
B(5,11,-1,minecraft:oak_leaves[distance=2,persistent=false])
B(5,15,-1,minecraft:oak_leaves)
B(5,16,-1,minecraft:oak_leaves)
B(5,17,-1,minecraft:oak_leaves)
B(5,19,-1,minecraft:oak_leaves[distance=2,persistent=false])
B(5,12,0,minecraft:oak_leaves)
B(5,13,0,minecraft:oak_log)
B(5,14,0,minecraft:oak_leaves)
B(5,16,0,minecraft:oak_log)
B(5,18,0,minecraft:oak_leaves[distance=3,persistent=false])
B(5,19,0,minecraft:oak_leaves[distance=3,persistent=false])
B(5,20,0,minecraft:oak_leaves[distance=4,persistent=false])
B(5,11,1,minecraft:oak_leaves[distance=2,persistent=false])
B(5,12,1,minecraft:oak_leaves[distance=2,persistent=false])
B(5,13,1,minecraft:oak_leaves)
B(5,15,1,minecraft:oak_leaves[distance=2,persistent=false])
B(5,16,1,minecraft:oak_leaves)
B(5,18,1,minecraft:oak_leaves[distance=4,persistent=false])
B(5,19,1,minecraft:oak_leaves[distance=4,persistent=false])
B(5,13,2,minecraft:oak_leaves[distance=2,persistent=false])
B(5,14,2,minecraft:oak_leaves)
B(5,15,2,minecraft:oak_leaves[distance=2,persistent=false])
B(5,16,2,minecraft:oak_leaves[distance=2,persistent=false])
B(5,17,2,minecraft:oak_leaves[distance=2,persistent=false])
B(5,18,2,minecraft:oak_leaves[distance=3,persistent=false])
B(5,11,3,minecraft:oak_leaves[distance=4,persistent=false])
B(5,12,3,minecraft:oak_leaves[distance=4,persistent=false])
B(5,14,3,minecraft:oak_leaves[distance=2,persistent=false])
B(5,15,3,minecraft:oak_leaves[distance=3,persistent=false])
B(5,16,3,minecraft:oak_leaves[distance=3,persistent=false])
B(5,17,3,minecraft:oak_leaves[distance=3,persistent=false])
B(6,13,-4,minecraft:oak_leaves[distance=4,persistent=false])
B(6,12,-3,minecraft:oak_leaves[distance=2,persistent=false])
B(6,13,-3,minecraft:oak_leaves[distance=3,persistent=false])
B(6,11,-2,minecraft:oak_leaves[distance=2,persistent=false])
B(6,12,-2,minecraft:oak_leaves)
B(6,13,-2,minecraft:oak_leaves[distance=2,persistent=false])
B(6,14,-2,minecraft:oak_leaves[distance=3,persistent=false])
B(6,15,-2,minecraft:oak_leaves[distance=3,persistent=false])
B(6,16,-2,minecraft:oak_leaves[distance=4,persistent=false])
B(6,17,-2,minecraft:oak_leaves[distance=3,persistent=false])
B(6,10,-1,minecraft:oak_leaves[distance=4,persistent=false])
B(6,12,-1,minecraft:oak_leaves[distance=2,persistent=false])
B(6,13,-1,minecraft:oak_leaves[distance=2,persistent=false])
B(6,14,-1,minecraft:oak_leaves[distance=3,persistent=false])
B(6,17,-1,minecraft:oak_leaves[distance=2,persistent=false])
B(6,11,0,minecraft:oak_leaves[distance=7,persistent=true])
B(6,13,0,minecraft:oak_leaves)
B(6,15,0,minecraft:oak_leaves)
B(6,16,0,minecraft:oak_log)
B(6,17,0,minecraft:oak_leaves)
B(6,18,0,minecraft:oak_leaves[distance=2,persistent=false])
B(6,14,1,minecraft:oak_leaves[distance=3,persistent=false])
B(6,17,1,minecraft:oak_leaves[distance=2,persistent=false])
B(6,18,1,minecraft:oak_leaves[distance=3,persistent=false])
B(6,13,2,minecraft:oak_leaves[distance=3,persistent=false])
B(6,14,2,minecraft:oak_leaves[distance=2,persistent=false])
B(6,15,2,minecraft:oak_leaves[distance=3,persistent=false])
B(6,16,2,minecraft:oak_leaves[distance=3,persistent=false])
B(6,17,2,minecraft:oak_leaves[distance=3,persistent=false])
B(6,18,2,minecraft:oak_leaves[distance=4,persistent=false])
B(6,14,3,minecraft:oak_leaves[distance=3,persistent=false])
B(6,16,3,minecraft:oak_leaves[distance=4,persistent=false])
B(7,11,-2,minecraft:oak_leaves[distance=3,persistent=false])
B(7,13,-2,minecraft:oak_leaves[distance=3,persistent=false])
B(7,15,-2,minecraft:oak_leaves[distance=4,persistent=false])
B(7,11,-1,minecraft:oak_leaves[distance=4,persistent=false])
B(7,13,-1,minecraft:oak_leaves[distance=3,persistent=false])
B(7,14,-1,minecraft:oak_leaves[distance=4,persistent=false])
B(7,15,-1,minecraft:oak_leaves[distance=3,persistent=false])
B(7,16,-1,minecraft:oak_leaves[distance=2,persistent=false])
B(7,13,0,minecraft:oak_leaves[distance=2,persistent=false])
B(7,14,0,minecraft:oak_leaves[distance=3,persistent=false])
B(7,15,0,minecraft:oak_leaves[distance=2,persistent=false])
B(7,16,0,minecraft:oak_leaves)
B(7,13,1,minecraft:oak_leaves[distance=3,persistent=false])
B(7,14,1,minecraft:oak_leaves[distance=4,persistent=false])
B(7,16,1,minecraft:oak_leaves[distance=2,persistent=false])
B(7,14,2,minecraft:oak_leaves[distance=3,persistent=false])

#######################################################################
# +-----------------------------------------------------------------+ #
# |                            BO3 checks                           | #
# +-----------------------------------------------------------------+ #
#######################################################################


#######################################################################
# +-----------------------------------------------------------------+ #
# |                             Branches                            | #
# +-----------------------------------------------------------------+ #
#######################################################################


#######################################################################
# +-----------------------------------------------------------------+ #
# |                             Entities                            | #
# +-----------------------------------------------------------------+ #
#######################################################################

