
#######################################################################
# +-----------------------------------------------------------------+ #
# |                            BO3 object                           | #
# +-----------------------------------------------------------------+ #
#######################################################################

Author: Unknown

Description: No description given

Version: 3

SettingsMode: WriteWithoutComments


#######################################################################
# +-----------------------------------------------------------------+ #
# |                          Main settings                          | #
# +-----------------------------------------------------------------+ #
#######################################################################

Tree: true

Frequency: 0

Rarity: 100.0

MaxSpawn: 0

RotateRandomly: false

SpawnHeight: highestBlock

SpawnHeightOffset: 0

SpawnHeightVariance: 0

##############################
# Height Limits for the BO3. #
##############################

MinHeight: 0

MaxHeight: 256

######################
# Extrusion settings #
######################

ExtrudeMode: None

ExtrudeThroughBlocks: minecraft:air

MaxBranchDepth: 10


#######################################################################
# +-----------------------------------------------------------------+ #
# |                      Source block settings                      | #
# +-----------------------------------------------------------------+ #
#######################################################################

SourceBlocks: minecraft:air

MaxPercentageOutsideSourceBlock: 100

OutsideSourceBlock: placeAnyway

DoReplaceBlocks: true

IsOTGPlus: false


#######################################################################
# +-----------------------------------------------------------------+ #
# |                              Blocks                             | #
# +-----------------------------------------------------------------+ #
#######################################################################

B(-6,10,0,minecraft:oak_leaves[distance=4,persistent=false])
B(-5,11,-2,minecraft:oak_leaves[distance=4,persistent=false])
B(-5,10,-1,minecraft:oak_leaves[distance=2,persistent=false])
B(-5,8,0,minecraft:oak_leaves[distance=5,persistent=false])
B(-5,9,0,minecraft:oak_leaves[distance=4,persistent=false])
B(-5,10,0,minecraft:oak_leaves[distance=3,persistent=false])
B(-5,12,0,minecraft:oak_leaves[distance=4,persistent=false])
B(-5,13,0,minecraft:oak_leaves[distance=5,persistent=false])
B(-5,9,1,minecraft:oak_leaves[distance=5,persistent=false])
B(-5,11,1,minecraft:oak_leaves[distance=2,persistent=false])
B(-5,9,2,minecraft:oak_leaves[distance=5,persistent=false])
B(-5,10,2,minecraft:oak_leaves[distance=4,persistent=false])
B(-5,11,2,minecraft:oak_leaves[distance=3,persistent=false])
B(-5,13,2,minecraft:oak_leaves[distance=7,persistent=true])
B(-5,11,3,minecraft:oak_leaves[distance=4,persistent=false])
B(-4,11,-3,minecraft:oak_leaves[distance=4,persistent=false])
B(-4,10,-2,minecraft:oak_leaves[distance=2,persistent=false])
B(-4,11,-2,minecraft:oak_leaves[distance=3,persistent=false])
B(-4,8,-1,minecraft:oak_leaves[distance=7,persistent=true])
B(-4,10,-1,minecraft:oak_leaves)
B(-4,13,-1,minecraft:oak_leaves[distance=5,persistent=false])
B(-4,7,0,minecraft:oak_leaves[distance=7,persistent=true])
B(-4,12,0,minecraft:oak_leaves[distance=3,persistent=false])
B(-4,13,0,minecraft:oak_leaves[distance=4,persistent=false])
B(-4,7,1,minecraft:oak_leaves[distance=7,persistent=true])
B(-4,8,1,minecraft:oak_leaves[distance=7,persistent=true])
B(-4,10,1,minecraft:oak_leaves[distance=2,persistent=false])
B(-4,11,1,minecraft:oak_leaves)
B(-4,12,1,minecraft:oak_leaves[distance=2,persistent=false])
B(-4,14,1,minecraft:oak_leaves[distance=7,persistent=true])
B(-4,7,2,minecraft:oak_leaves[distance=7,persistent=true])
B(-4,11,2,minecraft:oak_leaves[distance=2,persistent=false])
B(-4,8,3,minecraft:oak_leaves[distance=5,persistent=false])
B(-4,9,3,minecraft:oak_leaves[distance=4,persistent=false])
B(-4,10,3,minecraft:oak_leaves[distance=4,persistent=false])
B(-4,11,3,minecraft:oak_leaves[distance=3,persistent=false])
B(-4,12,3,minecraft:oak_leaves[distance=4,persistent=false])
B(-4,11,4,minecraft:oak_leaves[distance=2,persistent=false])
B(-3,11,-3,minecraft:oak_leaves[distance=3,persistent=false])
B(-3,12,-3,minecraft:oak_leaves[distance=2,persistent=false])
B(-3,14,-3,minecraft:oak_leaves[distance=7,persistent=true])
B(-3,10,-2,minecraft:oak_leaves)
B(-3,12,-2,minecraft:oak_leaves)
B(-3,13,-2,minecraft:oak_leaves[distance=2,persistent=false])
B(-3,9,-1,minecraft:oak_leaves)
B(-3,10,-1,minecraft:oak_log)
B(-3,11,-1,minecraft:oak_leaves)
B(-3,12,-1,minecraft:oak_leaves[distance=2,persistent=false])
B(-3,14,-1,minecraft:oak_leaves[distance=3,persistent=false])
B(-3,8,0,minecraft:oak_leaves[distance=3,persistent=false])
B(-3,10,0,minecraft:oak_leaves)
B(-3,11,0,minecraft:oak_leaves)
B(-3,13,0,minecraft:oak_leaves[distance=5,persistent=false])
B(-3,14,0,minecraft:oak_leaves[distance=4,persistent=false])
B(-3,9,1,minecraft:oak_log)
B(-3,11,1,minecraft:oak_log)
B(-3,12,1,minecraft:oak_leaves)
B(-3,10,2,minecraft:oak_leaves[distance=2,persistent=false])
B(-3,11,2,minecraft:oak_leaves)
B(-3,12,2,minecraft:oak_leaves[distance=2,persistent=false])
B(-3,14,2,minecraft:oak_leaves[distance=7,persistent=true])
B(-3,9,3,minecraft:oak_leaves[distance=3,persistent=false])
B(-3,10,3,minecraft:oak_leaves[distance=3,persistent=false])
B(-3,11,3,minecraft:oak_leaves[distance=2,persistent=false])
B(-3,13,3,minecraft:oak_leaves[distance=7,persistent=true])
B(-3,9,4,minecraft:oak_leaves[distance=3,persistent=false])
B(-3,10,4,minecraft:oak_leaves[distance=2,persistent=false])
B(-3,11,4,minecraft:oak_leaves)
B(-3,12,4,minecraft:oak_leaves[distance=2,persistent=false])
B(-3,12,5,minecraft:oak_leaves[distance=3,persistent=false])
B(-2,9,-3,minecraft:oak_leaves[distance=4,persistent=false])
B(-2,11,-3,minecraft:oak_leaves[distance=2,persistent=false])
B(-2,12,-3,minecraft:oak_leaves)
B(-2,14,-3,minecraft:oak_leaves[distance=7,persistent=true])
B(-2,9,-2,minecraft:oak_leaves[distance=3,persistent=false])
B(-2,10,-2,minecraft:oak_leaves[distance=2,persistent=false])
B(-2,11,-2,minecraft:oak_leaves)
B(-2,12,-2,minecraft:oak_log)
B(-2,13,-2,minecraft:oak_leaves)
B(-2,8,-1,minecraft:oak_leaves[distance=3,persistent=false])
B(-2,9,-1,minecraft:oak_leaves[distance=2,persistent=false])
B(-2,10,-1,minecraft:oak_leaves)
B(-2,11,-1,minecraft:oak_log)
B(-2,12,-1,minecraft:oak_leaves)
B(-2,13,-1,minecraft:oak_leaves)
B(-2,14,-1,minecraft:oak_leaves[distance=2,persistent=false])
B(-2,7,0,minecraft:oak_leaves)
B(-2,8,0,minecraft:oak_leaves[distance=2,persistent=false])
B(-2,9,0,minecraft:oak_leaves[distance=3,persistent=false])
B(-2,11,0,minecraft:oak_log)
B(-2,12,0,minecraft:oak_log)
B(-2,7,1,minecraft:oak_leaves[distance=2,persistent=false])
B(-2,10,1,minecraft:oak_log)
B(-2,12,1,minecraft:oak_leaves)
B(-2,14,1,minecraft:oak_leaves[distance=4,persistent=false])
B(-2,7,2,minecraft:oak_leaves[distance=3,persistent=false])
B(-2,8,2,minecraft:oak_leaves[distance=2,persistent=false])
B(-2,9,2,minecraft:oak_leaves)
B(-2,11,2,minecraft:oak_leaves[distance=2,persistent=false])
B(-2,12,2,minecraft:oak_leaves[distance=2,persistent=false])
B(-2,13,2,minecraft:oak_leaves[distance=3,persistent=false])
B(-2,15,2,minecraft:oak_leaves[distance=7,persistent=true])
B(-2,8,3,minecraft:oak_leaves[distance=3,persistent=false])
B(-2,9,3,minecraft:oak_leaves[distance=2,persistent=false])
B(-2,10,3,minecraft:oak_leaves[distance=2,persistent=false])
B(-2,11,3,minecraft:oak_leaves)
B(-2,14,3,minecraft:oak_leaves[distance=7,persistent=true])
B(-2,9,4,minecraft:oak_leaves[distance=3,persistent=false])
B(-2,11,4,minecraft:oak_log)
B(-2,13,4,minecraft:oak_leaves[distance=5,persistent=false])
B(-2,14,4,minecraft:oak_leaves[distance=6,persistent=false])
B(-2,8,5,minecraft:oak_leaves[distance=7,persistent=true])
B(-2,11,5,minecraft:oak_leaves)
B(-2,13,5,minecraft:oak_leaves[distance=4,persistent=false])
B(-2,10,6,minecraft:oak_leaves[distance=4,persistent=false])
B(-1,10,-5,minecraft:oak_leaves[distance=6,persistent=false])
B(-1,8,-4,minecraft:oak_leaves[distance=7,persistent=true])
B(-1,9,-4,minecraft:oak_leaves[distance=6,persistent=false])
B(-1,10,-4,minecraft:oak_leaves[distance=5,persistent=false])
B(-1,11,-4,minecraft:oak_leaves[distance=4,persistent=false])
B(-1,13,-4,minecraft:oak_leaves[distance=7,persistent=true])
B(-1,9,-3,minecraft:oak_leaves[distance=5,persistent=false])
B(-1,10,-3,minecraft:oak_leaves[distance=4,persistent=false])
B(-1,12,-3,minecraft:oak_leaves[distance=2,persistent=false])
B(-1,15,-3,minecraft:oak_leaves[distance=4,persistent=false])
B(-1,11,-2,minecraft:oak_leaves[distance=2,persistent=false])
B(-1,12,-2,minecraft:oak_leaves)
B(-1,13,-2,minecraft:oak_leaves)
B(-1,15,-2,minecraft:oak_leaves[distance=3,persistent=false])
B(-1,7,-1,minecraft:oak_leaves)
B(-1,11,-1,minecraft:oak_leaves)
B(-1,13,-1,minecraft:oak_log)
B(-1,14,-1,minecraft:oak_leaves)
B(-1,15,-1,minecraft:oak_leaves[distance=2,persistent=false])
B(-1,6,0,minecraft:oak_leaves)
B(-1,7,0,minecraft:oak_log)
B(-1,8,0,minecraft:oak_leaves)
B(-1,11,0,minecraft:oak_leaves)
B(-1,15,0,minecraft:oak_leaves[distance=3,persistent=false])
B(-1,0,1,minecraft:oak_log)
B(-1,1,1,minecraft:oak_log)
B(-1,8,1,minecraft:oak_leaves)
B(-1,9,1,minecraft:oak_leaves)
B(-1,10,1,minecraft:oak_leaves)
B(-1,13,1,minecraft:oak_leaves[distance=2,persistent=false])
B(-1,14,1,minecraft:oak_leaves[distance=3,persistent=false])
B(-1,15,1,minecraft:oak_leaves[distance=4,persistent=false])
B(-1,8,2,minecraft:oak_leaves)
B(-1,9,2,minecraft:oak_log)
B(-1,12,2,minecraft:oak_leaves[distance=3,persistent=false])
B(-1,7,3,minecraft:oak_leaves[distance=3,persistent=false])
B(-1,8,3,minecraft:oak_leaves[distance=2,persistent=false])
B(-1,9,3,minecraft:oak_leaves)
B(-1,10,3,minecraft:oak_leaves)
B(-1,11,3,minecraft:oak_log)
B(-1,13,3,minecraft:oak_log)
B(-1,15,3,minecraft:oak_leaves[distance=4,persistent=false])
B(-1,7,4,minecraft:oak_leaves[distance=4,persistent=false])
B(-1,8,4,minecraft:oak_leaves[distance=3,persistent=false])
B(-1,9,4,minecraft:oak_leaves[distance=2,persistent=false])
B(-1,14,4,minecraft:oak_leaves[distance=5,persistent=false])
B(-1,9,5,minecraft:oak_leaves[distance=3,persistent=false])
B(-1,10,5,minecraft:oak_leaves[distance=2,persistent=false])
B(-1,13,5,minecraft:oak_leaves[distance=3,persistent=false])
B(-1,14,5,minecraft:oak_leaves[distance=4,persistent=false])
B(-1,10,6,minecraft:oak_leaves[distance=3,persistent=false])
B(-1,11,6,minecraft:oak_leaves[distance=4,persistent=false])
B(-1,12,6,minecraft:oak_leaves[distance=3,persistent=false])
B(0,10,-5,minecraft:oak_leaves[distance=5,persistent=false])
B(0,11,-5,minecraft:oak_leaves[distance=4,persistent=false])
B(0,9,-4,minecraft:oak_leaves[distance=5,persistent=false])
B(0,10,-4,minecraft:oak_leaves[distance=4,persistent=false])
B(0,11,-4,minecraft:oak_leaves[distance=3,persistent=false])
B(0,12,-4,minecraft:oak_leaves[distance=4,persistent=false])
B(0,8,-3,minecraft:oak_leaves[distance=4,persistent=false])
B(0,9,-3,minecraft:oak_leaves[distance=4,persistent=false])
B(0,10,-3,minecraft:oak_leaves[distance=3,persistent=false])
B(0,12,-3,minecraft:oak_leaves[distance=3,persistent=false])
B(0,13,-3,minecraft:oak_leaves[distance=3,persistent=false])
B(0,14,-3,minecraft:oak_leaves[distance=4,persistent=false])
B(0,8,-2,minecraft:oak_leaves[distance=3,persistent=false])
B(0,9,-2,minecraft:oak_leaves[distance=3,persistent=false])
B(0,10,-2,minecraft:oak_leaves[distance=2,persistent=false])
B(0,11,-2,minecraft:oak_leaves)
B(0,8,-1,minecraft:oak_leaves[distance=2,persistent=false])
B(0,9,-1,minecraft:oak_leaves[distance=2,persistent=false])
B(0,10,-1,minecraft:oak_leaves)
B(0,11,-1,minecraft:oak_log)
B(0,12,-1,minecraft:oak_leaves)
B(0,13,-1,minecraft:oak_leaves)
B(0,0,0,minecraft:oak_log)
B(0,8,0,minecraft:oak_leaves)
B(0,10,0,minecraft:oak_leaves)
B(0,11,0,minecraft:oak_leaves)
B(0,12,0,minecraft:oak_log)
B(0,13,0,minecraft:oak_log)
B(0,14,0,minecraft:oak_leaves)
B(0,15,0,minecraft:oak_leaves[distance=2,persistent=false])
B(0,0,1,minecraft:oak_log)
B(0,1,1,minecraft:oak_log)
B(0,2,1,minecraft:oak_log)
B(0,3,1,minecraft:oak_log)
B(0,4,1,minecraft:oak_log)
B(0,5,1,minecraft:oak_log)
B(0,6,1,minecraft:oak_log)
B(0,7,1,minecraft:oak_log)
B(0,8,1,minecraft:oak_log)
B(0,9,1,minecraft:oak_log)
B(0,10,1,minecraft:oak_log)
B(0,11,1,minecraft:oak_log)
B(0,13,1,minecraft:oak_leaves)
B(0,0,2,minecraft:oak_log)
B(0,1,2,minecraft:oak_log)
B(0,2,2,minecraft:oak_log)
B(0,7,2,minecraft:oak_log)
B(0,8,2,minecraft:oak_log)
B(0,9,2,minecraft:oak_leaves)
B(0,10,2,minecraft:oak_leaves)
B(0,11,2,minecraft:oak_leaves)
B(0,13,2,minecraft:oak_leaves[distance=2,persistent=false])
B(0,14,2,minecraft:oak_leaves[distance=3,persistent=false])
B(0,15,2,minecraft:oak_leaves[distance=4,persistent=false])
B(0,16,2,minecraft:oak_leaves[distance=5,persistent=false])
B(0,9,3,minecraft:oak_log)
B(0,10,3,minecraft:oak_log)
B(0,11,3,minecraft:oak_log)
B(0,12,3,minecraft:oak_log)
B(0,13,3,minecraft:oak_leaves)
B(0,14,3,minecraft:oak_leaves[distance=2,persistent=false])
B(0,15,3,minecraft:oak_leaves[distance=3,persistent=false])
B(0,8,4,minecraft:oak_leaves[distance=2,persistent=false])
B(0,9,4,minecraft:oak_leaves)
B(0,10,4,minecraft:oak_leaves)
B(0,11,4,minecraft:oak_log)
B(0,12,4,minecraft:oak_leaves)
B(0,15,4,minecraft:oak_leaves[distance=4,persistent=false])
B(0,8,5,minecraft:oak_leaves[distance=3,persistent=false])
B(0,9,5,minecraft:oak_leaves[distance=2,persistent=false])
B(0,10,5,minecraft:oak_leaves)
B(0,11,5,minecraft:oak_log)
B(0,12,5,minecraft:oak_leaves)
B(0,13,5,minecraft:oak_leaves[distance=2,persistent=false])
B(0,10,6,minecraft:oak_leaves[distance=2,persistent=false])
B(0,12,6,minecraft:oak_leaves[distance=2,persistent=false])
B(1,11,-4,minecraft:oak_leaves[distance=2,persistent=false])
B(1,12,-4,minecraft:oak_leaves[distance=3,persistent=false])
B(1,9,-3,minecraft:oak_leaves[distance=3,persistent=false])
B(1,11,-3,minecraft:oak_leaves)
B(1,13,-3,minecraft:oak_leaves[distance=2,persistent=false])
B(1,15,-3,minecraft:oak_leaves[distance=7,persistent=true])
B(1,9,-2,minecraft:oak_leaves[distance=2,persistent=false])
B(1,10,-2,minecraft:oak_leaves)
B(1,11,-2,minecraft:oak_log)
B(1,12,-2,minecraft:oak_leaves)
B(1,13,-2,minecraft:oak_leaves)
B(1,14,-2,minecraft:oak_leaves[distance=2,persistent=false])
B(1,7,-1,minecraft:oak_leaves[distance=3,persistent=false])
B(1,8,-1,minecraft:oak_leaves[distance=2,persistent=false])
B(1,9,-1,minecraft:oak_leaves)
B(1,10,-1,minecraft:oak_log)
B(1,13,-1,minecraft:oak_log)
B(1,14,-1,minecraft:oak_leaves)
B(1,15,-1,minecraft:oak_leaves[distance=2,persistent=false])
B(1,9,0,minecraft:oak_log)
B(1,10,0,minecraft:oak_leaves)
B(1,11,0,minecraft:oak_leaves[distance=2,persistent=false])
B(1,14,0,minecraft:oak_leaves[distance=2,persistent=false])
B(1,15,0,minecraft:oak_leaves[distance=3,persistent=false])
B(1,8,1,minecraft:oak_log)
B(1,9,1,minecraft:oak_log)
B(1,12,1,minecraft:oak_log)
B(1,14,1,minecraft:oak_leaves[distance=3,persistent=false])
B(1,15,1,minecraft:oak_leaves[distance=4,persistent=false])
B(1,0,2,minecraft:oak_log)
B(1,8,2,minecraft:oak_leaves)
B(1,12,2,minecraft:oak_leaves)
B(1,8,3,minecraft:oak_leaves[distance=2,persistent=false])
B(1,10,3,minecraft:oak_leaves)
B(1,11,3,minecraft:oak_leaves)
B(1,12,3,minecraft:oak_leaves)
B(1,15,3,minecraft:oak_leaves[distance=4,persistent=false])
B(1,8,4,minecraft:oak_leaves[distance=3,persistent=false])
B(1,9,4,minecraft:oak_leaves[distance=2,persistent=false])
B(1,10,4,minecraft:oak_leaves[distance=2,persistent=false])
B(1,13,4,minecraft:oak_log)
B(1,14,4,minecraft:oak_leaves)
B(1,11,5,minecraft:oak_leaves)
B(1,12,5,minecraft:oak_leaves[distance=2,persistent=false])
B(1,13,5,minecraft:oak_leaves)
B(1,9,6,minecraft:oak_leaves[distance=4,persistent=false])
B(1,10,6,minecraft:oak_leaves[distance=3,persistent=false])
B(1,11,6,minecraft:oak_leaves[distance=2,persistent=false])
B(1,12,6,minecraft:oak_leaves[distance=3,persistent=false])
B(2,10,-4,minecraft:oak_leaves[distance=4,persistent=false])
B(2,12,-4,minecraft:oak_leaves[distance=4,persistent=false])
B(2,8,-3,minecraft:oak_leaves[distance=7,persistent=true])
B(2,10,-3,minecraft:oak_leaves[distance=3,persistent=false])
B(2,11,-3,minecraft:oak_leaves[distance=2,persistent=false])
B(2,9,-2,minecraft:oak_leaves)
B(2,11,-2,minecraft:oak_leaves)
B(2,12,-2,minecraft:oak_leaves[distance=2,persistent=false])
B(2,13,-2,minecraft:oak_leaves[distance=2,persistent=false])
B(2,15,-2,minecraft:oak_leaves[distance=4,persistent=false])
B(2,7,-1,minecraft:oak_leaves[distance=2,persistent=false])
B(2,8,-1,minecraft:oak_leaves)
B(2,9,-1,minecraft:oak_log)
B(2,10,-1,minecraft:oak_leaves)
B(2,11,-1,minecraft:oak_log)
B(2,13,-1,minecraft:oak_leaves)
B(2,15,-1,minecraft:oak_leaves[distance=3,persistent=false])
B(2,7,0,minecraft:oak_leaves[distance=3,persistent=false])
B(2,10,0,minecraft:oak_leaves[distance=2,persistent=false])
B(2,11,0,minecraft:oak_leaves)
B(2,13,0,minecraft:oak_leaves[distance=2,persistent=false])
B(2,9,1,minecraft:oak_leaves)
B(2,10,1,minecraft:oak_leaves)
B(2,13,1,minecraft:oak_leaves)
B(2,14,1,minecraft:oak_leaves[distance=2,persistent=false])
B(2,15,1,minecraft:oak_leaves[distance=3,persistent=false])
B(2,7,2,minecraft:oak_leaves[distance=7,persistent=true])
B(2,9,2,minecraft:oak_log)
B(2,10,2,minecraft:oak_log)
B(2,13,2,minecraft:oak_log)
B(2,15,2,minecraft:oak_leaves[distance=4,persistent=false])
B(2,16,2,minecraft:oak_leaves[distance=5,persistent=false])
B(2,8,3,minecraft:oak_leaves[distance=2,persistent=false])
B(2,9,3,minecraft:oak_leaves)
B(2,11,3,minecraft:oak_log)
B(2,12,3,minecraft:oak_leaves)
B(2,13,3,minecraft:oak_leaves)
B(2,14,3,minecraft:oak_leaves[distance=2,persistent=false])
B(2,15,3,minecraft:oak_leaves[distance=3,persistent=false])
B(2,8,4,minecraft:oak_leaves[distance=3,persistent=false])
B(2,10,4,minecraft:oak_leaves[distance=3,persistent=false])
B(2,12,4,minecraft:oak_leaves[distance=2,persistent=false])
B(2,14,4,minecraft:oak_leaves[distance=2,persistent=false])
B(2,10,5,minecraft:oak_leaves[distance=4,persistent=false])
B(2,13,5,minecraft:oak_leaves[distance=2,persistent=false])
B(2,11,6,minecraft:oak_leaves[distance=3,persistent=false])
B(2,12,6,minecraft:oak_leaves[distance=4,persistent=false])
B(3,9,-4,minecraft:oak_leaves[distance=7,persistent=true])
B(3,10,-3,minecraft:oak_leaves[distance=4,persistent=false])
B(3,12,-3,minecraft:oak_leaves[distance=5,persistent=false])
B(3,13,-3,minecraft:oak_leaves[distance=4,persistent=false])
B(3,8,-2,minecraft:oak_leaves[distance=3,persistent=false])
B(3,10,-2,minecraft:oak_leaves[distance=5,persistent=false])
B(3,13,-2,minecraft:oak_leaves[distance=3,persistent=false])
B(3,14,-2,minecraft:oak_leaves[distance=4,persistent=false])
B(3,7,-1,minecraft:oak_leaves[distance=3,persistent=false])
B(3,8,-1,minecraft:oak_leaves[distance=2,persistent=false])
B(3,11,-1,minecraft:oak_leaves)
B(3,13,-1,minecraft:oak_leaves[distance=2,persistent=false])
B(3,14,-1,minecraft:oak_leaves[distance=3,persistent=false])
B(3,7,0,minecraft:oak_leaves[distance=4,persistent=false])
B(3,8,0,minecraft:oak_leaves[distance=3,persistent=false])
B(3,9,0,minecraft:oak_leaves[distance=4,persistent=false])
B(3,10,0,minecraft:oak_leaves[distance=3,persistent=false])
B(3,12,0,minecraft:oak_leaves[distance=2,persistent=false])
B(3,14,0,minecraft:oak_leaves[distance=2,persistent=false])
B(3,15,0,minecraft:oak_leaves[distance=3,persistent=false])
B(3,8,1,minecraft:oak_leaves[distance=4,persistent=false])
B(3,11,1,minecraft:oak_leaves)
B(3,12,1,minecraft:oak_leaves)
B(3,13,1,minecraft:oak_log)
B(3,14,1,minecraft:oak_leaves)
B(3,15,1,minecraft:oak_leaves[distance=2,persistent=false])
B(3,7,2,minecraft:oak_leaves[distance=6,persistent=false])
B(3,8,2,minecraft:oak_leaves[distance=5,persistent=false])
B(3,10,2,minecraft:oak_leaves)
B(3,11,2,minecraft:oak_log)
B(3,12,2,minecraft:oak_log)
B(3,13,2,minecraft:oak_leaves)
B(3,9,3,minecraft:oak_leaves[distance=2,persistent=false])
B(3,10,3,minecraft:oak_leaves[distance=2,persistent=false])
B(3,11,3,minecraft:oak_leaves)
B(3,12,3,minecraft:oak_leaves)
B(3,13,3,minecraft:oak_leaves[distance=2,persistent=false])
B(3,14,3,minecraft:oak_leaves[distance=3,persistent=false])
B(3,9,4,minecraft:oak_leaves[distance=3,persistent=false])
B(3,10,4,minecraft:oak_leaves[distance=3,persistent=false])
B(3,14,4,minecraft:oak_leaves[distance=3,persistent=false])
B(3,11,5,minecraft:oak_leaves[distance=7,persistent=true])
B(3,14,5,minecraft:oak_leaves[distance=4,persistent=false])
B(4,12,-3,minecraft:oak_leaves[distance=6,persistent=false])
B(4,11,-2,minecraft:oak_leaves[distance=3,persistent=false])
B(4,13,-2,minecraft:oak_leaves[distance=4,persistent=false])
B(4,9,-1,minecraft:oak_leaves[distance=7,persistent=true])
B(4,11,-1,minecraft:oak_leaves[distance=2,persistent=false])
B(4,12,-1,minecraft:oak_leaves[distance=3,persistent=false])
B(4,13,-1,minecraft:oak_leaves[distance=3,persistent=false])
B(4,10,0,minecraft:oak_leaves[distance=4,persistent=false])
B(4,11,0,minecraft:oak_leaves[distance=3,persistent=false])
B(4,12,0,minecraft:oak_leaves[distance=2,persistent=false])
B(4,14,0,minecraft:oak_leaves[distance=2,persistent=false])
B(4,15,0,minecraft:oak_leaves[distance=3,persistent=false])
B(4,8,1,minecraft:oak_leaves[distance=5,persistent=false])
B(4,10,1,minecraft:oak_leaves[distance=3,persistent=false])
B(4,11,1,minecraft:oak_leaves[distance=2,persistent=false])
B(4,12,1,minecraft:oak_leaves)
B(4,13,1,minecraft:oak_log)
B(4,14,1,minecraft:oak_leaves)
B(4,15,1,minecraft:oak_leaves[distance=2,persistent=false])
B(4,8,2,minecraft:oak_leaves[distance=4,persistent=false])
B(4,9,2,minecraft:oak_leaves[distance=3,persistent=false])
B(4,10,2,minecraft:oak_leaves[distance=2,persistent=false])
B(4,12,2,minecraft:oak_leaves)
B(4,14,2,minecraft:oak_leaves[distance=2,persistent=false])
B(4,15,2,minecraft:oak_leaves[distance=3,persistent=false])
B(4,9,3,minecraft:oak_leaves[distance=3,persistent=false])
B(4,10,3,minecraft:oak_leaves[distance=2,persistent=false])
B(4,11,3,minecraft:oak_leaves)
B(4,12,3,minecraft:oak_log)
B(4,13,3,minecraft:oak_leaves)
B(4,12,4,minecraft:oak_leaves)
B(4,13,4,minecraft:oak_leaves[distance=2,persistent=false])
B(4,13,5,minecraft:oak_leaves[distance=3,persistent=false])
B(5,12,-1,minecraft:oak_leaves[distance=4,persistent=false])
B(5,13,-1,minecraft:oak_leaves[distance=3,persistent=false])
B(5,11,0,minecraft:oak_leaves[distance=4,persistent=false])
B(5,13,0,minecraft:oak_leaves[distance=2,persistent=false])
B(5,14,0,minecraft:oak_leaves[distance=3,persistent=false])
B(5,13,1,minecraft:oak_leaves)
B(5,9,2,minecraft:oak_leaves[distance=4,persistent=false])
B(5,11,2,minecraft:oak_leaves[distance=3,persistent=false])
B(5,12,2,minecraft:oak_leaves[distance=2,persistent=false])
B(5,15,2,minecraft:oak_leaves[distance=4,persistent=false])
B(5,11,3,minecraft:oak_leaves[distance=2,persistent=false])
B(5,14,3,minecraft:oak_leaves[distance=7,persistent=true])
B(5,12,4,minecraft:oak_leaves[distance=2,persistent=false])
B(5,13,4,minecraft:oak_leaves[distance=3,persistent=false])
B(6,12,0,minecraft:oak_leaves[distance=4,persistent=false])
B(6,12,1,minecraft:oak_leaves[distance=3,persistent=false])
B(6,13,1,minecraft:oak_leaves[distance=2,persistent=false])
B(6,14,2,minecraft:oak_leaves[distance=7,persistent=true])

#######################################################################
# +-----------------------------------------------------------------+ #
# |                            BO3 checks                           | #
# +-----------------------------------------------------------------+ #
#######################################################################


#######################################################################
# +-----------------------------------------------------------------+ #
# |                             Branches                            | #
# +-----------------------------------------------------------------+ #
#######################################################################


#######################################################################
# +-----------------------------------------------------------------+ #
# |                             Entities                            | #
# +-----------------------------------------------------------------+ #
#######################################################################

